2019-01-24 10:27:42,222 [Thread-3:34112] [django.request:152] [base:get_response] [WARNING]- Not Found: /favicon.ico
2019-01-24 10:30:45,324 [Thread-8:30452] [django.request:152] [base:get_response] [WARNING]- Not Found: /favicon.ico
2019-01-24 11:21:34,018 [Thread-4:31520] [django.request:135] [exception:handle_uncaught_exception] [ERROR]- Internal Server Error: /
Traceback (most recent call last):
  File "C:\Users\liqihua\AppData\Local\Programs\Python\Python35\lib\site-packages\django\core\handlers\exception.py", line 41, in inner
    response = get_response(request)
  File "C:\Users\liqihua\AppData\Local\Programs\Python\Python35\lib\site-packages\django\core\handlers\base.py", line 187, in _get_response
    response = self.process_exception_by_middleware(e, request)
  File "C:\Users\liqihua\AppData\Local\Programs\Python\Python35\lib\site-packages\django\core\handlers\base.py", line 185, in _get_response
    response = wrapped_callback(request, *callback_args, **callback_kwargs)
  File "D:\stealproject\web\django2\django2\views.py", line 66, in login
    loginmark(username)
  File "D:\stealproject\web\django2\django2\views.py", line 29, in loginmark
    uid = userinfo.objects.filter(username=ausername).values()[0]['userid']
  File "C:\Users\liqihua\AppData\Local\Programs\Python\Python35\lib\site-packages\django\db\models\query.py", line 289, in __getitem__
    return list(qs)[0]
IndexError: list index out of range
2019-01-24 14:28:29,578 [Thread-3:34276] [django.request:152] [base:get_response] [WARNING]- Not Found: /favicon.ico
2019-01-24 15:29:03,369 [Thread-3:7160] [django.request:152] [base:get_response] [WARNING]- Not Found: /favicon.ico
2019-01-24 15:29:06,126 [Thread-4:36260] [django.request:135] [exception:handle_uncaught_exception] [ERROR]- Internal Server Error: /
Traceback (most recent call last):
  File "C:\Users\liqihua\AppData\Local\Programs\Python\Python35\lib\site-packages\django\core\handlers\exception.py", line 41, in inner
    response = get_response(request)
  File "C:\Users\liqihua\AppData\Local\Programs\Python\Python35\lib\site-packages\django\core\handlers\base.py", line 187, in _get_response
    response = self.process_exception_by_middleware(e, request)
  File "C:\Users\liqihua\AppData\Local\Programs\Python\Python35\lib\site-packages\django\core\handlers\base.py", line 185, in _get_response
    response = wrapped_callback(request, *callback_args, **callback_kwargs)
  File "D:\stealproject\web\django2\django2\views.py", line 66, in login
    loginmark(username)
  File "D:\stealproject\web\django2\django2\views.py", line 30, in loginmark
    loginhistory.objects.create(userid=uid,username=ausername)
  File "C:\Users\liqihua\AppData\Local\Programs\Python\Python35\lib\site-packages\django\db\models\manager.py", line 85, in manager_method
    return getattr(self.get_queryset(), name)(*args, **kwargs)
  File "C:\Users\liqihua\AppData\Local\Programs\Python\Python35\lib\site-packages\django\db\models\query.py", line 393, in create
    obj.save(force_insert=True, using=self.db)
  File "C:\Users\liqihua\AppData\Local\Programs\Python\Python35\lib\site-packages\django\db\models\base.py", line 806, in save
    force_update=force_update, update_fields=update_fields)
  File "C:\Users\liqihua\AppData\Local\Programs\Python\Python35\lib\site-packages\django\db\models\base.py", line 836, in save_base
    updated = self._save_table(raw, cls, force_insert, force_update, using, update_fields)
  File "C:\Users\liqihua\AppData\Local\Programs\Python\Python35\lib\site-packages\django\db\models\base.py", line 922, in _save_table
    result = self._do_insert(cls._base_manager, using, fields, update_pk, raw)
  File "C:\Users\liqihua\AppData\Local\Programs\Python\Python35\lib\site-packages\django\db\models\base.py", line 961, in _do_insert
    using=using, raw=raw)
  File "C:\Users\liqihua\AppData\Local\Programs\Python\Python35\lib\site-packages\django\db\models\manager.py", line 85, in manager_method
    return getattr(self.get_queryset(), name)(*args, **kwargs)
  File "C:\Users\liqihua\AppData\Local\Programs\Python\Python35\lib\site-packages\django\db\models\query.py", line 1060, in _insert
    return query.get_compiler(using=using).execute_sql(return_id)
  File "C:\Users\liqihua\AppData\Local\Programs\Python\Python35\lib\site-packages\django\db\models\sql\compiler.py", line 1106, in execute_sql
    return self.connection.ops.fetch_returned_insert_id(cursor)
  File "C:\Users\liqihua\AppData\Local\Programs\Python\Python35\lib\site-packages\django\db\backends\oracle\operations.py", line 245, in fetch_returned_insert_id
    return int(cursor._insert_id_var.getvalue())
TypeError: int() argument must be a string, a bytes-like object or a number, not 'list'
2019-01-24 15:29:16,721 [Thread-6:37440] [django.request:135] [exception:handle_uncaught_exception] [ERROR]- Internal Server Error: /
Traceback (most recent call last):
  File "C:\Users\liqihua\AppData\Local\Programs\Python\Python35\lib\site-packages\django\core\handlers\exception.py", line 41, in inner
    response = get_response(request)
  File "C:\Users\liqihua\AppData\Local\Programs\Python\Python35\lib\site-packages\django\core\handlers\base.py", line 187, in _get_response
    response = self.process_exception_by_middleware(e, request)
  File "C:\Users\liqihua\AppData\Local\Programs\Python\Python35\lib\site-packages\django\core\handlers\base.py", line 185, in _get_response
    response = wrapped_callback(request, *callback_args, **callback_kwargs)
  File "D:\stealproject\web\django2\django2\views.py", line 66, in login
    loginmark(username)
  File "D:\stealproject\web\django2\django2\views.py", line 30, in loginmark
    loginhistory.objects.create(userid=uid,username=ausername)
  File "C:\Users\liqihua\AppData\Local\Programs\Python\Python35\lib\site-packages\django\db\models\manager.py", line 85, in manager_method
    return getattr(self.get_queryset(), name)(*args, **kwargs)
  File "C:\Users\liqihua\AppData\Local\Programs\Python\Python35\lib\site-packages\django\db\models\query.py", line 393, in create
    obj.save(force_insert=True, using=self.db)
  File "C:\Users\liqihua\AppData\Local\Programs\Python\Python35\lib\site-packages\django\db\models\base.py", line 806, in save
    force_update=force_update, update_fields=update_fields)
  File "C:\Users\liqihua\AppData\Local\Programs\Python\Python35\lib\site-packages\django\db\models\base.py", line 836, in save_base
    updated = self._save_table(raw, cls, force_insert, force_update, using, update_fields)
  File "C:\Users\liqihua\AppData\Local\Programs\Python\Python35\lib\site-packages\django\db\models\base.py", line 922, in _save_table
    result = self._do_insert(cls._base_manager, using, fields, update_pk, raw)
  File "C:\Users\liqihua\AppData\Local\Programs\Python\Python35\lib\site-packages\django\db\models\base.py", line 961, in _do_insert
    using=using, raw=raw)
  File "C:\Users\liqihua\AppData\Local\Programs\Python\Python35\lib\site-packages\django\db\models\manager.py", line 85, in manager_method
    return getattr(self.get_queryset(), name)(*args, **kwargs)
  File "C:\Users\liqihua\AppData\Local\Programs\Python\Python35\lib\site-packages\django\db\models\query.py", line 1060, in _insert
    return query.get_compiler(using=using).execute_sql(return_id)
  File "C:\Users\liqihua\AppData\Local\Programs\Python\Python35\lib\site-packages\django\db\models\sql\compiler.py", line 1106, in execute_sql
    return self.connection.ops.fetch_returned_insert_id(cursor)
  File "C:\Users\liqihua\AppData\Local\Programs\Python\Python35\lib\site-packages\django\db\backends\oracle\operations.py", line 245, in fetch_returned_insert_id
    return int(cursor._insert_id_var.getvalue())
TypeError: int() argument must be a string, a bytes-like object or a number, not 'list'
2019-01-24 15:31:11,781 [Thread-3:35892] [django.request:135] [exception:handle_uncaught_exception] [ERROR]- Internal Server Error: /
Traceback (most recent call last):
  File "C:\Users\liqihua\AppData\Local\Programs\Python\Python35\lib\site-packages\django\core\handlers\exception.py", line 41, in inner
    response = get_response(request)
  File "C:\Users\liqihua\AppData\Local\Programs\Python\Python35\lib\site-packages\django\core\handlers\base.py", line 187, in _get_response
    response = self.process_exception_by_middleware(e, request)
  File "C:\Users\liqihua\AppData\Local\Programs\Python\Python35\lib\site-packages\django\core\handlers\base.py", line 185, in _get_response
    response = wrapped_callback(request, *callback_args, **callback_kwargs)
  File "D:\stealproject\web\django2\django2\views.py", line 67, in login
    loginmark(username)
  File "D:\stealproject\web\django2\django2\views.py", line 31, in loginmark
    loginhistory.objects.create(userid=uid,username=ausername)
  File "C:\Users\liqihua\AppData\Local\Programs\Python\Python35\lib\site-packages\django\db\models\manager.py", line 85, in manager_method
    return getattr(self.get_queryset(), name)(*args, **kwargs)
  File "C:\Users\liqihua\AppData\Local\Programs\Python\Python35\lib\site-packages\django\db\models\query.py", line 393, in create
    obj.save(force_insert=True, using=self.db)
  File "C:\Users\liqihua\AppData\Local\Programs\Python\Python35\lib\site-packages\django\db\models\base.py", line 806, in save
    force_update=force_update, update_fields=update_fields)
  File "C:\Users\liqihua\AppData\Local\Programs\Python\Python35\lib\site-packages\django\db\models\base.py", line 836, in save_base
    updated = self._save_table(raw, cls, force_insert, force_update, using, update_fields)
  File "C:\Users\liqihua\AppData\Local\Programs\Python\Python35\lib\site-packages\django\db\models\base.py", line 922, in _save_table
    result = self._do_insert(cls._base_manager, using, fields, update_pk, raw)
  File "C:\Users\liqihua\AppData\Local\Programs\Python\Python35\lib\site-packages\django\db\models\base.py", line 961, in _do_insert
    using=using, raw=raw)
  File "C:\Users\liqihua\AppData\Local\Programs\Python\Python35\lib\site-packages\django\db\models\manager.py", line 85, in manager_method
    return getattr(self.get_queryset(), name)(*args, **kwargs)
  File "C:\Users\liqihua\AppData\Local\Programs\Python\Python35\lib\site-packages\django\db\models\query.py", line 1060, in _insert
    return query.get_compiler(using=using).execute_sql(return_id)
  File "C:\Users\liqihua\AppData\Local\Programs\Python\Python35\lib\site-packages\django\db\models\sql\compiler.py", line 1106, in execute_sql
    return self.connection.ops.fetch_returned_insert_id(cursor)
  File "C:\Users\liqihua\AppData\Local\Programs\Python\Python35\lib\site-packages\django\db\backends\oracle\operations.py", line 245, in fetch_returned_insert_id
    return int(cursor._insert_id_var.getvalue())
TypeError: int() argument must be a string, a bytes-like object or a number, not 'list'
2019-01-24 15:31:48,040 [Thread-3:24636] [django.request:135] [exception:handle_uncaught_exception] [ERROR]- Internal Server Error: /
Traceback (most recent call last):
  File "C:\Users\liqihua\AppData\Local\Programs\Python\Python35\lib\site-packages\django\core\handlers\exception.py", line 41, in inner
    response = get_response(request)
  File "C:\Users\liqihua\AppData\Local\Programs\Python\Python35\lib\site-packages\django\core\handlers\base.py", line 187, in _get_response
    response = self.process_exception_by_middleware(e, request)
  File "C:\Users\liqihua\AppData\Local\Programs\Python\Python35\lib\site-packages\django\core\handlers\base.py", line 185, in _get_response
    response = wrapped_callback(request, *callback_args, **callback_kwargs)
  File "D:\stealproject\web\django2\django2\views.py", line 67, in login
    loginmark(username)
  File "D:\stealproject\web\django2\django2\views.py", line 31, in loginmark
    loginhistory.objects.create(userid=uid,username=ausername)
  File "C:\Users\liqihua\AppData\Local\Programs\Python\Python35\lib\site-packages\django\db\models\manager.py", line 85, in manager_method
    return getattr(self.get_queryset(), name)(*args, **kwargs)
  File "C:\Users\liqihua\AppData\Local\Programs\Python\Python35\lib\site-packages\django\db\models\query.py", line 393, in create
    obj.save(force_insert=True, using=self.db)
  File "C:\Users\liqihua\AppData\Local\Programs\Python\Python35\lib\site-packages\django\db\models\base.py", line 806, in save
    force_update=force_update, update_fields=update_fields)
  File "C:\Users\liqihua\AppData\Local\Programs\Python\Python35\lib\site-packages\django\db\models\base.py", line 836, in save_base
    updated = self._save_table(raw, cls, force_insert, force_update, using, update_fields)
  File "C:\Users\liqihua\AppData\Local\Programs\Python\Python35\lib\site-packages\django\db\models\base.py", line 922, in _save_table
    result = self._do_insert(cls._base_manager, using, fields, update_pk, raw)
  File "C:\Users\liqihua\AppData\Local\Programs\Python\Python35\lib\site-packages\django\db\models\base.py", line 961, in _do_insert
    using=using, raw=raw)
  File "C:\Users\liqihua\AppData\Local\Programs\Python\Python35\lib\site-packages\django\db\models\manager.py", line 85, in manager_method
    return getattr(self.get_queryset(), name)(*args, **kwargs)
  File "C:\Users\liqihua\AppData\Local\Programs\Python\Python35\lib\site-packages\django\db\models\query.py", line 1060, in _insert
    return query.get_compiler(using=using).execute_sql(return_id)
  File "C:\Users\liqihua\AppData\Local\Programs\Python\Python35\lib\site-packages\django\db\models\sql\compiler.py", line 1106, in execute_sql
    return self.connection.ops.fetch_returned_insert_id(cursor)
  File "C:\Users\liqihua\AppData\Local\Programs\Python\Python35\lib\site-packages\django\db\backends\oracle\operations.py", line 245, in fetch_returned_insert_id
    return int(cursor._insert_id_var.getvalue())
TypeError: int() argument must be a string, a bytes-like object or a number, not 'list'
2019-01-24 15:32:35,012 [Thread-8:34636] [django.request:135] [exception:handle_uncaught_exception] [ERROR]- Internal Server Error: /admin/
Traceback (most recent call last):
  File "C:\Users\liqihua\AppData\Local\Programs\Python\Python35\lib\site-packages\django\db\backends\utils.py", line 65, in execute
    return self.cursor.execute(sql, params)
  File "C:\Users\liqihua\AppData\Local\Programs\Python\Python35\lib\site-packages\django\db\backends\oracle\base.py", line 479, in execute
    return self.cursor.execute(query, self._param_generator(params))
cx_Oracle.IntegrityError: ORA-00001: unique constraint (SCOTT.SYS_C0012212) violated

The above exception was the direct cause of the following exception:

Traceback (most recent call last):
  File "C:\Users\liqihua\AppData\Local\Programs\Python\Python35\lib\site-packages\django\core\handlers\exception.py", line 41, in inner
    response = get_response(request)
  File "C:\Users\liqihua\AppData\Local\Programs\Python\Python35\lib\site-packages\django\core\handlers\base.py", line 187, in _get_response
    response = self.process_exception_by_middleware(e, request)
  File "C:\Users\liqihua\AppData\Local\Programs\Python\Python35\lib\site-packages\django\core\handlers\base.py", line 185, in _get_response
    response = wrapped_callback(request, *callback_args, **callback_kwargs)
  File "D:\stealproject\web\django2\django2\views.py", line 89, in admin
    data = adminadd(username, usercode, usertype)
  File "D:\stealproject\web\django2\django2\views.py", line 37, in adminadd
    userinfo.objects.create(userid=k+1,username=ausername, password=busercode, type=cusertype)
  File "C:\Users\liqihua\AppData\Local\Programs\Python\Python35\lib\site-packages\django\db\models\manager.py", line 85, in manager_method
    return getattr(self.get_queryset(), name)(*args, **kwargs)
  File "C:\Users\liqihua\AppData\Local\Programs\Python\Python35\lib\site-packages\django\db\models\query.py", line 393, in create
    obj.save(force_insert=True, using=self.db)
  File "C:\Users\liqihua\AppData\Local\Programs\Python\Python35\lib\site-packages\django\db\models\base.py", line 806, in save
    force_update=force_update, update_fields=update_fields)
  File "C:\Users\liqihua\AppData\Local\Programs\Python\Python35\lib\site-packages\django\db\models\base.py", line 836, in save_base
    updated = self._save_table(raw, cls, force_insert, force_update, using, update_fields)
  File "C:\Users\liqihua\AppData\Local\Programs\Python\Python35\lib\site-packages\django\db\models\base.py", line 922, in _save_table
    result = self._do_insert(cls._base_manager, using, fields, update_pk, raw)
  File "C:\Users\liqihua\AppData\Local\Programs\Python\Python35\lib\site-packages\django\db\models\base.py", line 961, in _do_insert
    using=using, raw=raw)
  File "C:\Users\liqihua\AppData\Local\Programs\Python\Python35\lib\site-packages\django\db\models\manager.py", line 85, in manager_method
    return getattr(self.get_queryset(), name)(*args, **kwargs)
  File "C:\Users\liqihua\AppData\Local\Programs\Python\Python35\lib\site-packages\django\db\models\query.py", line 1060, in _insert
    return query.get_compiler(using=using).execute_sql(return_id)
  File "C:\Users\liqihua\AppData\Local\Programs\Python\Python35\lib\site-packages\django\db\models\sql\compiler.py", line 1099, in execute_sql
    cursor.execute(sql, params)
  File "C:\Users\liqihua\AppData\Local\Programs\Python\Python35\lib\site-packages\django\db\backends\utils.py", line 80, in execute
    return super(CursorDebugWrapper, self).execute(sql, params)
  File "C:\Users\liqihua\AppData\Local\Programs\Python\Python35\lib\site-packages\django\db\backends\utils.py", line 65, in execute
    return self.cursor.execute(sql, params)
  File "C:\Users\liqihua\AppData\Local\Programs\Python\Python35\lib\site-packages\django\db\utils.py", line 94, in __exit__
    six.reraise(dj_exc_type, dj_exc_value, traceback)
  File "C:\Users\liqihua\AppData\Local\Programs\Python\Python35\lib\site-packages\django\utils\six.py", line 685, in reraise
    raise value.with_traceback(tb)
  File "C:\Users\liqihua\AppData\Local\Programs\Python\Python35\lib\site-packages\django\db\backends\utils.py", line 65, in execute
    return self.cursor.execute(sql, params)
  File "C:\Users\liqihua\AppData\Local\Programs\Python\Python35\lib\site-packages\django\db\backends\oracle\base.py", line 479, in execute
    return self.cursor.execute(query, self._param_generator(params))
django.db.utils.IntegrityError: ORA-00001: unique constraint (SCOTT.SYS_C0012212) violated
2019-01-24 15:33:14,038 [Thread-3:37056] [django.request:135] [exception:handle_uncaught_exception] [ERROR]- Internal Server Error: /
Traceback (most recent call last):
  File "C:\Users\liqihua\AppData\Local\Programs\Python\Python35\lib\site-packages\django\core\handlers\exception.py", line 41, in inner
    response = get_response(request)
  File "C:\Users\liqihua\AppData\Local\Programs\Python\Python35\lib\site-packages\django\core\handlers\base.py", line 187, in _get_response
    response = self.process_exception_by_middleware(e, request)
  File "C:\Users\liqihua\AppData\Local\Programs\Python\Python35\lib\site-packages\django\core\handlers\base.py", line 185, in _get_response
    response = wrapped_callback(request, *callback_args, **callback_kwargs)
  File "D:\stealproject\web\django2\django2\views.py", line 67, in login
    loginmark(username)
  File "D:\stealproject\web\django2\django2\views.py", line 31, in loginmark
    loginhistory.objects.create(userid=uid,username=ausername)
  File "C:\Users\liqihua\AppData\Local\Programs\Python\Python35\lib\site-packages\django\db\models\manager.py", line 85, in manager_method
    return getattr(self.get_queryset(), name)(*args, **kwargs)
  File "C:\Users\liqihua\AppData\Local\Programs\Python\Python35\lib\site-packages\django\db\models\query.py", line 393, in create
    obj.save(force_insert=True, using=self.db)
  File "C:\Users\liqihua\AppData\Local\Programs\Python\Python35\lib\site-packages\django\db\models\base.py", line 806, in save
    force_update=force_update, update_fields=update_fields)
  File "C:\Users\liqihua\AppData\Local\Programs\Python\Python35\lib\site-packages\django\db\models\base.py", line 836, in save_base
    updated = self._save_table(raw, cls, force_insert, force_update, using, update_fields)
  File "C:\Users\liqihua\AppData\Local\Programs\Python\Python35\lib\site-packages\django\db\models\base.py", line 922, in _save_table
    result = self._do_insert(cls._base_manager, using, fields, update_pk, raw)
  File "C:\Users\liqihua\AppData\Local\Programs\Python\Python35\lib\site-packages\django\db\models\base.py", line 961, in _do_insert
    using=using, raw=raw)
  File "C:\Users\liqihua\AppData\Local\Programs\Python\Python35\lib\site-packages\django\db\models\manager.py", line 85, in manager_method
    return getattr(self.get_queryset(), name)(*args, **kwargs)
  File "C:\Users\liqihua\AppData\Local\Programs\Python\Python35\lib\site-packages\django\db\models\query.py", line 1060, in _insert
    return query.get_compiler(using=using).execute_sql(return_id)
  File "C:\Users\liqihua\AppData\Local\Programs\Python\Python35\lib\site-packages\django\db\models\sql\compiler.py", line 1106, in execute_sql
    return self.connection.ops.fetch_returned_insert_id(cursor)
  File "C:\Users\liqihua\AppData\Local\Programs\Python\Python35\lib\site-packages\django\db\backends\oracle\operations.py", line 245, in fetch_returned_insert_id
    return int(cursor._insert_id_var.getvalue())
TypeError: int() argument must be a string, a bytes-like object or a number, not 'list'
2019-01-24 15:38:04,951 [Thread-3:35832] [django.request:135] [exception:handle_uncaught_exception] [ERROR]- Internal Server Error: /
Traceback (most recent call last):
  File "C:\Users\liqihua\AppData\Local\Programs\Python\Python35\lib\site-packages\django\core\handlers\exception.py", line 41, in inner
    response = get_response(request)
  File "C:\Users\liqihua\AppData\Local\Programs\Python\Python35\lib\site-packages\django\core\handlers\base.py", line 187, in _get_response
    response = self.process_exception_by_middleware(e, request)
  File "C:\Users\liqihua\AppData\Local\Programs\Python\Python35\lib\site-packages\django\core\handlers\base.py", line 185, in _get_response
    response = wrapped_callback(request, *callback_args, **callback_kwargs)
  File "D:\stealproject\web\django2\django2\views.py", line 67, in login
    loginmark(username)
  File "D:\stealproject\web\django2\django2\views.py", line 31, in loginmark
    loginhistory.objects.create(userid=uid,username=ausername)
  File "C:\Users\liqihua\AppData\Local\Programs\Python\Python35\lib\site-packages\django\db\models\manager.py", line 85, in manager_method
    return getattr(self.get_queryset(), name)(*args, **kwargs)
  File "C:\Users\liqihua\AppData\Local\Programs\Python\Python35\lib\site-packages\django\db\models\query.py", line 393, in create
    obj.save(force_insert=True, using=self.db)
  File "C:\Users\liqihua\AppData\Local\Programs\Python\Python35\lib\site-packages\django\db\models\base.py", line 806, in save
    force_update=force_update, update_fields=update_fields)
  File "C:\Users\liqihua\AppData\Local\Programs\Python\Python35\lib\site-packages\django\db\models\base.py", line 836, in save_base
    updated = self._save_table(raw, cls, force_insert, force_update, using, update_fields)
  File "C:\Users\liqihua\AppData\Local\Programs\Python\Python35\lib\site-packages\django\db\models\base.py", line 922, in _save_table
    result = self._do_insert(cls._base_manager, using, fields, update_pk, raw)
  File "C:\Users\liqihua\AppData\Local\Programs\Python\Python35\lib\site-packages\django\db\models\base.py", line 961, in _do_insert
    using=using, raw=raw)
  File "C:\Users\liqihua\AppData\Local\Programs\Python\Python35\lib\site-packages\django\db\models\manager.py", line 85, in manager_method
    return getattr(self.get_queryset(), name)(*args, **kwargs)
  File "C:\Users\liqihua\AppData\Local\Programs\Python\Python35\lib\site-packages\django\db\models\query.py", line 1060, in _insert
    return query.get_compiler(using=using).execute_sql(return_id)
  File "C:\Users\liqihua\AppData\Local\Programs\Python\Python35\lib\site-packages\django\db\models\sql\compiler.py", line 1106, in execute_sql
    return self.connection.ops.fetch_returned_insert_id(cursor)
  File "C:\Users\liqihua\AppData\Local\Programs\Python\Python35\lib\site-packages\django\db\backends\oracle\operations.py", line 245, in fetch_returned_insert_id
    return int(cursor._insert_id_var.getvalue())
TypeError: int() argument must be a string, a bytes-like object or a number, not 'list'
2019-01-24 15:39:49,792 [Thread-6:38592] [django.request:152] [base:get_response] [WARNING]- Not Found: /favicon.ico
2019-01-24 15:39:51,838 [Thread-7:38812] [django.request:135] [exception:handle_uncaught_exception] [ERROR]- Internal Server Error: /
Traceback (most recent call last):
  File "C:\Users\liqihua\AppData\Local\Programs\Python\Python35\lib\site-packages\django\core\handlers\exception.py", line 41, in inner
    response = get_response(request)
  File "C:\Users\liqihua\AppData\Local\Programs\Python\Python35\lib\site-packages\django\core\handlers\base.py", line 187, in _get_response
    response = self.process_exception_by_middleware(e, request)
  File "C:\Users\liqihua\AppData\Local\Programs\Python\Python35\lib\site-packages\django\core\handlers\base.py", line 185, in _get_response
    response = wrapped_callback(request, *callback_args, **callback_kwargs)
  File "D:\stealproject\web\django2\django2\views.py", line 67, in login
    loginmark(username)
  File "D:\stealproject\web\django2\django2\views.py", line 31, in loginmark
    loginhistory.objects.create(userid=uid,username=ausername)
  File "C:\Users\liqihua\AppData\Local\Programs\Python\Python35\lib\site-packages\django\db\models\manager.py", line 85, in manager_method
    return getattr(self.get_queryset(), name)(*args, **kwargs)
  File "C:\Users\liqihua\AppData\Local\Programs\Python\Python35\lib\site-packages\django\db\models\query.py", line 393, in create
    obj.save(force_insert=True, using=self.db)
  File "C:\Users\liqihua\AppData\Local\Programs\Python\Python35\lib\site-packages\django\db\models\base.py", line 806, in save
    force_update=force_update, update_fields=update_fields)
  File "C:\Users\liqihua\AppData\Local\Programs\Python\Python35\lib\site-packages\django\db\models\base.py", line 836, in save_base
    updated = self._save_table(raw, cls, force_insert, force_update, using, update_fields)
  File "C:\Users\liqihua\AppData\Local\Programs\Python\Python35\lib\site-packages\django\db\models\base.py", line 922, in _save_table
    result = self._do_insert(cls._base_manager, using, fields, update_pk, raw)
  File "C:\Users\liqihua\AppData\Local\Programs\Python\Python35\lib\site-packages\django\db\models\base.py", line 961, in _do_insert
    using=using, raw=raw)
  File "C:\Users\liqihua\AppData\Local\Programs\Python\Python35\lib\site-packages\django\db\models\manager.py", line 85, in manager_method
    return getattr(self.get_queryset(), name)(*args, **kwargs)
  File "C:\Users\liqihua\AppData\Local\Programs\Python\Python35\lib\site-packages\django\db\models\query.py", line 1060, in _insert
    return query.get_compiler(using=using).execute_sql(return_id)
  File "C:\Users\liqihua\AppData\Local\Programs\Python\Python35\lib\site-packages\django\db\models\sql\compiler.py", line 1106, in execute_sql
    return self.connection.ops.fetch_returned_insert_id(cursor)
  File "C:\Users\liqihua\AppData\Local\Programs\Python\Python35\lib\site-packages\django\db\backends\oracle\operations.py", line 245, in fetch_returned_insert_id
    return int(cursor._insert_id_var.getvalue())
TypeError: int() argument must be a string, a bytes-like object or a number, not 'list'
2019-01-24 15:40:47,969 [Thread-3:11204] [django.request:135] [exception:handle_uncaught_exception] [ERROR]- Internal Server Error: /
Traceback (most recent call last):
  File "C:\Users\liqihua\AppData\Local\Programs\Python\Python35\lib\site-packages\django\db\backends\utils.py", line 65, in execute
    return self.cursor.execute(sql, params)
  File "C:\Users\liqihua\AppData\Local\Programs\Python\Python35\lib\site-packages\django\db\backends\oracle\base.py", line 479, in execute
    return self.cursor.execute(query, self._param_generator(params))
cx_Oracle.IntegrityError: ORA-01400: cannot insert NULL into ("SCOTT"."DJANGO2_LOGINHISTORY"."USERID")

The above exception was the direct cause of the following exception:

Traceback (most recent call last):
  File "C:\Users\liqihua\AppData\Local\Programs\Python\Python35\lib\site-packages\django\core\handlers\exception.py", line 41, in inner
    response = get_response(request)
  File "C:\Users\liqihua\AppData\Local\Programs\Python\Python35\lib\site-packages\django\core\handlers\base.py", line 187, in _get_response
    response = self.process_exception_by_middleware(e, request)
  File "C:\Users\liqihua\AppData\Local\Programs\Python\Python35\lib\site-packages\django\core\handlers\base.py", line 185, in _get_response
    response = wrapped_callback(request, *callback_args, **callback_kwargs)
  File "D:\stealproject\web\django2\django2\views.py", line 67, in login
    loginmark(username)
  File "D:\stealproject\web\django2\django2\views.py", line 31, in loginmark
    loginhistory.objects.create(username=ausername)
  File "C:\Users\liqihua\AppData\Local\Programs\Python\Python35\lib\site-packages\django\db\models\manager.py", line 85, in manager_method
    return getattr(self.get_queryset(), name)(*args, **kwargs)
  File "C:\Users\liqihua\AppData\Local\Programs\Python\Python35\lib\site-packages\django\db\models\query.py", line 393, in create
    obj.save(force_insert=True, using=self.db)
  File "C:\Users\liqihua\AppData\Local\Programs\Python\Python35\lib\site-packages\django\db\models\base.py", line 806, in save
    force_update=force_update, update_fields=update_fields)
  File "C:\Users\liqihua\AppData\Local\Programs\Python\Python35\lib\site-packages\django\db\models\base.py", line 836, in save_base
    updated = self._save_table(raw, cls, force_insert, force_update, using, update_fields)
  File "C:\Users\liqihua\AppData\Local\Programs\Python\Python35\lib\site-packages\django\db\models\base.py", line 922, in _save_table
    result = self._do_insert(cls._base_manager, using, fields, update_pk, raw)
  File "C:\Users\liqihua\AppData\Local\Programs\Python\Python35\lib\site-packages\django\db\models\base.py", line 961, in _do_insert
    using=using, raw=raw)
  File "C:\Users\liqihua\AppData\Local\Programs\Python\Python35\lib\site-packages\django\db\models\manager.py", line 85, in manager_method
    return getattr(self.get_queryset(), name)(*args, **kwargs)
  File "C:\Users\liqihua\AppData\Local\Programs\Python\Python35\lib\site-packages\django\db\models\query.py", line 1060, in _insert
    return query.get_compiler(using=using).execute_sql(return_id)
  File "C:\Users\liqihua\AppData\Local\Programs\Python\Python35\lib\site-packages\django\db\models\sql\compiler.py", line 1099, in execute_sql
    cursor.execute(sql, params)
  File "C:\Users\liqihua\AppData\Local\Programs\Python\Python35\lib\site-packages\django\db\backends\utils.py", line 80, in execute
    return super(CursorDebugWrapper, self).execute(sql, params)
  File "C:\Users\liqihua\AppData\Local\Programs\Python\Python35\lib\site-packages\django\db\backends\utils.py", line 65, in execute
    return self.cursor.execute(sql, params)
  File "C:\Users\liqihua\AppData\Local\Programs\Python\Python35\lib\site-packages\django\db\utils.py", line 94, in __exit__
    six.reraise(dj_exc_type, dj_exc_value, traceback)
  File "C:\Users\liqihua\AppData\Local\Programs\Python\Python35\lib\site-packages\django\utils\six.py", line 685, in reraise
    raise value.with_traceback(tb)
  File "C:\Users\liqihua\AppData\Local\Programs\Python\Python35\lib\site-packages\django\db\backends\utils.py", line 65, in execute
    return self.cursor.execute(sql, params)
  File "C:\Users\liqihua\AppData\Local\Programs\Python\Python35\lib\site-packages\django\db\backends\oracle\base.py", line 479, in execute
    return self.cursor.execute(query, self._param_generator(params))
django.db.utils.IntegrityError: ORA-01400: cannot insert NULL into ("SCOTT"."DJANGO2_LOGINHISTORY"."USERID")
2019-01-24 15:41:08,029 [Thread-3:35216] [django.request:135] [exception:handle_uncaught_exception] [ERROR]- Internal Server Error: /
Traceback (most recent call last):
  File "C:\Users\liqihua\AppData\Local\Programs\Python\Python35\lib\site-packages\django\core\handlers\exception.py", line 41, in inner
    response = get_response(request)
  File "C:\Users\liqihua\AppData\Local\Programs\Python\Python35\lib\site-packages\django\core\handlers\base.py", line 187, in _get_response
    response = self.process_exception_by_middleware(e, request)
  File "C:\Users\liqihua\AppData\Local\Programs\Python\Python35\lib\site-packages\django\core\handlers\base.py", line 185, in _get_response
    response = wrapped_callback(request, *callback_args, **callback_kwargs)
  File "D:\stealproject\web\django2\django2\views.py", line 67, in login
    loginmark(username)
  File "D:\stealproject\web\django2\django2\views.py", line 31, in loginmark
    loginhistory.objects.create(userid=uid)
  File "C:\Users\liqihua\AppData\Local\Programs\Python\Python35\lib\site-packages\django\db\models\manager.py", line 85, in manager_method
    return getattr(self.get_queryset(), name)(*args, **kwargs)
  File "C:\Users\liqihua\AppData\Local\Programs\Python\Python35\lib\site-packages\django\db\models\query.py", line 393, in create
    obj.save(force_insert=True, using=self.db)
  File "C:\Users\liqihua\AppData\Local\Programs\Python\Python35\lib\site-packages\django\db\models\base.py", line 806, in save
    force_update=force_update, update_fields=update_fields)
  File "C:\Users\liqihua\AppData\Local\Programs\Python\Python35\lib\site-packages\django\db\models\base.py", line 836, in save_base
    updated = self._save_table(raw, cls, force_insert, force_update, using, update_fields)
  File "C:\Users\liqihua\AppData\Local\Programs\Python\Python35\lib\site-packages\django\db\models\base.py", line 922, in _save_table
    result = self._do_insert(cls._base_manager, using, fields, update_pk, raw)
  File "C:\Users\liqihua\AppData\Local\Programs\Python\Python35\lib\site-packages\django\db\models\base.py", line 961, in _do_insert
    using=using, raw=raw)
  File "C:\Users\liqihua\AppData\Local\Programs\Python\Python35\lib\site-packages\django\db\models\manager.py", line 85, in manager_method
    return getattr(self.get_queryset(), name)(*args, **kwargs)
  File "C:\Users\liqihua\AppData\Local\Programs\Python\Python35\lib\site-packages\django\db\models\query.py", line 1060, in _insert
    return query.get_compiler(using=using).execute_sql(return_id)
  File "C:\Users\liqihua\AppData\Local\Programs\Python\Python35\lib\site-packages\django\db\models\sql\compiler.py", line 1106, in execute_sql
    return self.connection.ops.fetch_returned_insert_id(cursor)
  File "C:\Users\liqihua\AppData\Local\Programs\Python\Python35\lib\site-packages\django\db\backends\oracle\operations.py", line 245, in fetch_returned_insert_id
    return int(cursor._insert_id_var.getvalue())
TypeError: int() argument must be a string, a bytes-like object or a number, not 'list'
2019-01-24 15:42:27,201 [Thread-3:38384] [django.request:135] [exception:handle_uncaught_exception] [ERROR]- Internal Server Error: /
Traceback (most recent call last):
  File "C:\Users\liqihua\AppData\Local\Programs\Python\Python35\lib\site-packages\django\core\handlers\exception.py", line 41, in inner
    response = get_response(request)
  File "C:\Users\liqihua\AppData\Local\Programs\Python\Python35\lib\site-packages\django\core\handlers\base.py", line 187, in _get_response
    response = self.process_exception_by_middleware(e, request)
  File "C:\Users\liqihua\AppData\Local\Programs\Python\Python35\lib\site-packages\django\core\handlers\base.py", line 185, in _get_response
    response = wrapped_callback(request, *callback_args, **callback_kwargs)
  File "D:\stealproject\web\django2\django2\views.py", line 68, in login
    loginmark(username)
  File "D:\stealproject\web\django2\django2\views.py", line 32, in loginmark
    loginhistory.objects.create(userid=uid,username=ausername)
  File "C:\Users\liqihua\AppData\Local\Programs\Python\Python35\lib\site-packages\django\db\models\manager.py", line 85, in manager_method
    return getattr(self.get_queryset(), name)(*args, **kwargs)
  File "C:\Users\liqihua\AppData\Local\Programs\Python\Python35\lib\site-packages\django\db\models\query.py", line 393, in create
    obj.save(force_insert=True, using=self.db)
  File "C:\Users\liqihua\AppData\Local\Programs\Python\Python35\lib\site-packages\django\db\models\base.py", line 806, in save
    force_update=force_update, update_fields=update_fields)
  File "C:\Users\liqihua\AppData\Local\Programs\Python\Python35\lib\site-packages\django\db\models\base.py", line 836, in save_base
    updated = self._save_table(raw, cls, force_insert, force_update, using, update_fields)
  File "C:\Users\liqihua\AppData\Local\Programs\Python\Python35\lib\site-packages\django\db\models\base.py", line 922, in _save_table
    result = self._do_insert(cls._base_manager, using, fields, update_pk, raw)
  File "C:\Users\liqihua\AppData\Local\Programs\Python\Python35\lib\site-packages\django\db\models\base.py", line 961, in _do_insert
    using=using, raw=raw)
  File "C:\Users\liqihua\AppData\Local\Programs\Python\Python35\lib\site-packages\django\db\models\manager.py", line 85, in manager_method
    return getattr(self.get_queryset(), name)(*args, **kwargs)
  File "C:\Users\liqihua\AppData\Local\Programs\Python\Python35\lib\site-packages\django\db\models\query.py", line 1060, in _insert
    return query.get_compiler(using=using).execute_sql(return_id)
  File "C:\Users\liqihua\AppData\Local\Programs\Python\Python35\lib\site-packages\django\db\models\sql\compiler.py", line 1106, in execute_sql
    return self.connection.ops.fetch_returned_insert_id(cursor)
  File "C:\Users\liqihua\AppData\Local\Programs\Python\Python35\lib\site-packages\django\db\backends\oracle\operations.py", line 245, in fetch_returned_insert_id
    return int(cursor._insert_id_var.getvalue())
TypeError: int() argument must be a string, a bytes-like object or a number, not 'list'
2019-01-24 15:42:44,697 [Thread-3:34900] [django.request:135] [exception:handle_uncaught_exception] [ERROR]- Internal Server Error: /
Traceback (most recent call last):
  File "C:\Users\liqihua\AppData\Local\Programs\Python\Python35\lib\site-packages\django\core\handlers\exception.py", line 41, in inner
    response = get_response(request)
  File "C:\Users\liqihua\AppData\Local\Programs\Python\Python35\lib\site-packages\django\core\handlers\base.py", line 187, in _get_response
    response = self.process_exception_by_middleware(e, request)
  File "C:\Users\liqihua\AppData\Local\Programs\Python\Python35\lib\site-packages\django\core\handlers\base.py", line 185, in _get_response
    response = wrapped_callback(request, *callback_args, **callback_kwargs)
  File "D:\stealproject\web\django2\django2\views.py", line 68, in login
    loginmark(username)
  File "D:\stealproject\web\django2\django2\views.py", line 32, in loginmark
    loginhistory.objects.create(userid=2,username=ausername)
  File "C:\Users\liqihua\AppData\Local\Programs\Python\Python35\lib\site-packages\django\db\models\manager.py", line 85, in manager_method
    return getattr(self.get_queryset(), name)(*args, **kwargs)
  File "C:\Users\liqihua\AppData\Local\Programs\Python\Python35\lib\site-packages\django\db\models\query.py", line 393, in create
    obj.save(force_insert=True, using=self.db)
  File "C:\Users\liqihua\AppData\Local\Programs\Python\Python35\lib\site-packages\django\db\models\base.py", line 806, in save
    force_update=force_update, update_fields=update_fields)
  File "C:\Users\liqihua\AppData\Local\Programs\Python\Python35\lib\site-packages\django\db\models\base.py", line 836, in save_base
    updated = self._save_table(raw, cls, force_insert, force_update, using, update_fields)
  File "C:\Users\liqihua\AppData\Local\Programs\Python\Python35\lib\site-packages\django\db\models\base.py", line 922, in _save_table
    result = self._do_insert(cls._base_manager, using, fields, update_pk, raw)
  File "C:\Users\liqihua\AppData\Local\Programs\Python\Python35\lib\site-packages\django\db\models\base.py", line 961, in _do_insert
    using=using, raw=raw)
  File "C:\Users\liqihua\AppData\Local\Programs\Python\Python35\lib\site-packages\django\db\models\manager.py", line 85, in manager_method
    return getattr(self.get_queryset(), name)(*args, **kwargs)
  File "C:\Users\liqihua\AppData\Local\Programs\Python\Python35\lib\site-packages\django\db\models\query.py", line 1060, in _insert
    return query.get_compiler(using=using).execute_sql(return_id)
  File "C:\Users\liqihua\AppData\Local\Programs\Python\Python35\lib\site-packages\django\db\models\sql\compiler.py", line 1106, in execute_sql
    return self.connection.ops.fetch_returned_insert_id(cursor)
  File "C:\Users\liqihua\AppData\Local\Programs\Python\Python35\lib\site-packages\django\db\backends\oracle\operations.py", line 245, in fetch_returned_insert_id
    return int(cursor._insert_id_var.getvalue())
TypeError: int() argument must be a string, a bytes-like object or a number, not 'list'
2019-01-24 15:55:15,412 [Thread-3:22900] [django.request:152] [base:get_response] [WARNING]- Not Found: /favicon.ico
2019-01-24 15:57:15,580 [Thread-3:36164] [django.request:152] [base:get_response] [WARNING]- Not Found: /favicon.ico
