2019-01-24 10:27:42,222 [Thread-3:34112] [django.request:152] [base:get_response] [WARNING]- Not Found: /favicon.ico
2019-01-24 10:30:45,324 [Thread-8:30452] [django.request:152] [base:get_response] [WARNING]- Not Found: /favicon.ico
2019-01-24 11:21:34,018 [Thread-4:31520] [django.request:135] [exception:handle_uncaught_exception] [ERROR]- Internal Server Error: /
Traceback (most recent call last):
  File "C:\Users\liqihua\AppData\Local\Programs\Python\Python35\lib\site-packages\django\core\handlers\exception.py", line 41, in inner
    response = get_response(request)
  File "C:\Users\liqihua\AppData\Local\Programs\Python\Python35\lib\site-packages\django\core\handlers\base.py", line 187, in _get_response
    response = self.process_exception_by_middleware(e, request)
  File "C:\Users\liqihua\AppData\Local\Programs\Python\Python35\lib\site-packages\django\core\handlers\base.py", line 185, in _get_response
    response = wrapped_callback(request, *callback_args, **callback_kwargs)
  File "D:\stealproject\web\django2\django2\views.py", line 66, in login
    loginmark(username)
  File "D:\stealproject\web\django2\django2\views.py", line 29, in loginmark
    uid = userinfo.objects.filter(username=ausername).values()[0]['userid']
  File "C:\Users\liqihua\AppData\Local\Programs\Python\Python35\lib\site-packages\django\db\models\query.py", line 289, in __getitem__
    return list(qs)[0]
IndexError: list index out of range
2019-01-24 14:28:29,578 [Thread-3:34276] [django.request:152] [base:get_response] [WARNING]- Not Found: /favicon.ico
2019-01-24 15:29:03,369 [Thread-3:7160] [django.request:152] [base:get_response] [WARNING]- Not Found: /favicon.ico
2019-01-24 15:29:06,126 [Thread-4:36260] [django.request:135] [exception:handle_uncaught_exception] [ERROR]- Internal Server Error: /
Traceback (most recent call last):
  File "C:\Users\liqihua\AppData\Local\Programs\Python\Python35\lib\site-packages\django\core\handlers\exception.py", line 41, in inner
    response = get_response(request)
  File "C:\Users\liqihua\AppData\Local\Programs\Python\Python35\lib\site-packages\django\core\handlers\base.py", line 187, in _get_response
    response = self.process_exception_by_middleware(e, request)
  File "C:\Users\liqihua\AppData\Local\Programs\Python\Python35\lib\site-packages\django\core\handlers\base.py", line 185, in _get_response
    response = wrapped_callback(request, *callback_args, **callback_kwargs)
  File "D:\stealproject\web\django2\django2\views.py", line 66, in login
    loginmark(username)
  File "D:\stealproject\web\django2\django2\views.py", line 30, in loginmark
    loginhistory.objects.create(userid=uid,username=ausername)
  File "C:\Users\liqihua\AppData\Local\Programs\Python\Python35\lib\site-packages\django\db\models\manager.py", line 85, in manager_method
    return getattr(self.get_queryset(), name)(*args, **kwargs)
  File "C:\Users\liqihua\AppData\Local\Programs\Python\Python35\lib\site-packages\django\db\models\query.py", line 393, in create
    obj.save(force_insert=True, using=self.db)
  File "C:\Users\liqihua\AppData\Local\Programs\Python\Python35\lib\site-packages\django\db\models\base.py", line 806, in save
    force_update=force_update, update_fields=update_fields)
  File "C:\Users\liqihua\AppData\Local\Programs\Python\Python35\lib\site-packages\django\db\models\base.py", line 836, in save_base
    updated = self._save_table(raw, cls, force_insert, force_update, using, update_fields)
  File "C:\Users\liqihua\AppData\Local\Programs\Python\Python35\lib\site-packages\django\db\models\base.py", line 922, in _save_table
    result = self._do_insert(cls._base_manager, using, fields, update_pk, raw)
  File "C:\Users\liqihua\AppData\Local\Programs\Python\Python35\lib\site-packages\django\db\models\base.py", line 961, in _do_insert
    using=using, raw=raw)
  File "C:\Users\liqihua\AppData\Local\Programs\Python\Python35\lib\site-packages\django\db\models\manager.py", line 85, in manager_method
    return getattr(self.get_queryset(), name)(*args, **kwargs)
  File "C:\Users\liqihua\AppData\Local\Programs\Python\Python35\lib\site-packages\django\db\models\query.py", line 1060, in _insert
    return query.get_compiler(using=using).execute_sql(return_id)
  File "C:\Users\liqihua\AppData\Local\Programs\Python\Python35\lib\site-packages\django\db\models\sql\compiler.py", line 1106, in execute_sql
    return self.connection.ops.fetch_returned_insert_id(cursor)
  File "C:\Users\liqihua\AppData\Local\Programs\Python\Python35\lib\site-packages\django\db\backends\oracle\operations.py", line 245, in fetch_returned_insert_id
    return int(cursor._insert_id_var.getvalue())
TypeError: int() argument must be a string, a bytes-like object or a number, not 'list'
2019-01-24 15:29:16,721 [Thread-6:37440] [django.request:135] [exception:handle_uncaught_exception] [ERROR]- Internal Server Error: /
Traceback (most recent call last):
  File "C:\Users\liqihua\AppData\Local\Programs\Python\Python35\lib\site-packages\django\core\handlers\exception.py", line 41, in inner
    response = get_response(request)
  File "C:\Users\liqihua\AppData\Local\Programs\Python\Python35\lib\site-packages\django\core\handlers\base.py", line 187, in _get_response
    response = self.process_exception_by_middleware(e, request)
  File "C:\Users\liqihua\AppData\Local\Programs\Python\Python35\lib\site-packages\django\core\handlers\base.py", line 185, in _get_response
    response = wrapped_callback(request, *callback_args, **callback_kwargs)
  File "D:\stealproject\web\django2\django2\views.py", line 66, in login
    loginmark(username)
  File "D:\stealproject\web\django2\django2\views.py", line 30, in loginmark
    loginhistory.objects.create(userid=uid,username=ausername)
  File "C:\Users\liqihua\AppData\Local\Programs\Python\Python35\lib\site-packages\django\db\models\manager.py", line 85, in manager_method
    return getattr(self.get_queryset(), name)(*args, **kwargs)
  File "C:\Users\liqihua\AppData\Local\Programs\Python\Python35\lib\site-packages\django\db\models\query.py", line 393, in create
    obj.save(force_insert=True, using=self.db)
  File "C:\Users\liqihua\AppData\Local\Programs\Python\Python35\lib\site-packages\django\db\models\base.py", line 806, in save
    force_update=force_update, update_fields=update_fields)
  File "C:\Users\liqihua\AppData\Local\Programs\Python\Python35\lib\site-packages\django\db\models\base.py", line 836, in save_base
    updated = self._save_table(raw, cls, force_insert, force_update, using, update_fields)
  File "C:\Users\liqihua\AppData\Local\Programs\Python\Python35\lib\site-packages\django\db\models\base.py", line 922, in _save_table
    result = self._do_insert(cls._base_manager, using, fields, update_pk, raw)
  File "C:\Users\liqihua\AppData\Local\Programs\Python\Python35\lib\site-packages\django\db\models\base.py", line 961, in _do_insert
    using=using, raw=raw)
  File "C:\Users\liqihua\AppData\Local\Programs\Python\Python35\lib\site-packages\django\db\models\manager.py", line 85, in manager_method
    return getattr(self.get_queryset(), name)(*args, **kwargs)
  File "C:\Users\liqihua\AppData\Local\Programs\Python\Python35\lib\site-packages\django\db\models\query.py", line 1060, in _insert
    return query.get_compiler(using=using).execute_sql(return_id)
  File "C:\Users\liqihua\AppData\Local\Programs\Python\Python35\lib\site-packages\django\db\models\sql\compiler.py", line 1106, in execute_sql
    return self.connection.ops.fetch_returned_insert_id(cursor)
  File "C:\Users\liqihua\AppData\Local\Programs\Python\Python35\lib\site-packages\django\db\backends\oracle\operations.py", line 245, in fetch_returned_insert_id
    return int(cursor._insert_id_var.getvalue())
TypeError: int() argument must be a string, a bytes-like object or a number, not 'list'
2019-01-24 15:31:11,781 [Thread-3:35892] [django.request:135] [exception:handle_uncaught_exception] [ERROR]- Internal Server Error: /
Traceback (most recent call last):
  File "C:\Users\liqihua\AppData\Local\Programs\Python\Python35\lib\site-packages\django\core\handlers\exception.py", line 41, in inner
    response = get_response(request)
  File "C:\Users\liqihua\AppData\Local\Programs\Python\Python35\lib\site-packages\django\core\handlers\base.py", line 187, in _get_response
    response = self.process_exception_by_middleware(e, request)
  File "C:\Users\liqihua\AppData\Local\Programs\Python\Python35\lib\site-packages\django\core\handlers\base.py", line 185, in _get_response
    response = wrapped_callback(request, *callback_args, **callback_kwargs)
  File "D:\stealproject\web\django2\django2\views.py", line 67, in login
    loginmark(username)
  File "D:\stealproject\web\django2\django2\views.py", line 31, in loginmark
    loginhistory.objects.create(userid=uid,username=ausername)
  File "C:\Users\liqihua\AppData\Local\Programs\Python\Python35\lib\site-packages\django\db\models\manager.py", line 85, in manager_method
    return getattr(self.get_queryset(), name)(*args, **kwargs)
  File "C:\Users\liqihua\AppData\Local\Programs\Python\Python35\lib\site-packages\django\db\models\query.py", line 393, in create
    obj.save(force_insert=True, using=self.db)
  File "C:\Users\liqihua\AppData\Local\Programs\Python\Python35\lib\site-packages\django\db\models\base.py", line 806, in save
    force_update=force_update, update_fields=update_fields)
  File "C:\Users\liqihua\AppData\Local\Programs\Python\Python35\lib\site-packages\django\db\models\base.py", line 836, in save_base
    updated = self._save_table(raw, cls, force_insert, force_update, using, update_fields)
  File "C:\Users\liqihua\AppData\Local\Programs\Python\Python35\lib\site-packages\django\db\models\base.py", line 922, in _save_table
    result = self._do_insert(cls._base_manager, using, fields, update_pk, raw)
  File "C:\Users\liqihua\AppData\Local\Programs\Python\Python35\lib\site-packages\django\db\models\base.py", line 961, in _do_insert
    using=using, raw=raw)
  File "C:\Users\liqihua\AppData\Local\Programs\Python\Python35\lib\site-packages\django\db\models\manager.py", line 85, in manager_method
    return getattr(self.get_queryset(), name)(*args, **kwargs)
  File "C:\Users\liqihua\AppData\Local\Programs\Python\Python35\lib\site-packages\django\db\models\query.py", line 1060, in _insert
    return query.get_compiler(using=using).execute_sql(return_id)
  File "C:\Users\liqihua\AppData\Local\Programs\Python\Python35\lib\site-packages\django\db\models\sql\compiler.py", line 1106, in execute_sql
    return self.connection.ops.fetch_returned_insert_id(cursor)
  File "C:\Users\liqihua\AppData\Local\Programs\Python\Python35\lib\site-packages\django\db\backends\oracle\operations.py", line 245, in fetch_returned_insert_id
    return int(cursor._insert_id_var.getvalue())
TypeError: int() argument must be a string, a bytes-like object or a number, not 'list'
2019-01-24 15:31:48,040 [Thread-3:24636] [django.request:135] [exception:handle_uncaught_exception] [ERROR]- Internal Server Error: /
Traceback (most recent call last):
  File "C:\Users\liqihua\AppData\Local\Programs\Python\Python35\lib\site-packages\django\core\handlers\exception.py", line 41, in inner
    response = get_response(request)
  File "C:\Users\liqihua\AppData\Local\Programs\Python\Python35\lib\site-packages\django\core\handlers\base.py", line 187, in _get_response
    response = self.process_exception_by_middleware(e, request)
  File "C:\Users\liqihua\AppData\Local\Programs\Python\Python35\lib\site-packages\django\core\handlers\base.py", line 185, in _get_response
    response = wrapped_callback(request, *callback_args, **callback_kwargs)
  File "D:\stealproject\web\django2\django2\views.py", line 67, in login
    loginmark(username)
  File "D:\stealproject\web\django2\django2\views.py", line 31, in loginmark
    loginhistory.objects.create(userid=uid,username=ausername)
  File "C:\Users\liqihua\AppData\Local\Programs\Python\Python35\lib\site-packages\django\db\models\manager.py", line 85, in manager_method
    return getattr(self.get_queryset(), name)(*args, **kwargs)
  File "C:\Users\liqihua\AppData\Local\Programs\Python\Python35\lib\site-packages\django\db\models\query.py", line 393, in create
    obj.save(force_insert=True, using=self.db)
  File "C:\Users\liqihua\AppData\Local\Programs\Python\Python35\lib\site-packages\django\db\models\base.py", line 806, in save
    force_update=force_update, update_fields=update_fields)
  File "C:\Users\liqihua\AppData\Local\Programs\Python\Python35\lib\site-packages\django\db\models\base.py", line 836, in save_base
    updated = self._save_table(raw, cls, force_insert, force_update, using, update_fields)
  File "C:\Users\liqihua\AppData\Local\Programs\Python\Python35\lib\site-packages\django\db\models\base.py", line 922, in _save_table
    result = self._do_insert(cls._base_manager, using, fields, update_pk, raw)
  File "C:\Users\liqihua\AppData\Local\Programs\Python\Python35\lib\site-packages\django\db\models\base.py", line 961, in _do_insert
    using=using, raw=raw)
  File "C:\Users\liqihua\AppData\Local\Programs\Python\Python35\lib\site-packages\django\db\models\manager.py", line 85, in manager_method
    return getattr(self.get_queryset(), name)(*args, **kwargs)
  File "C:\Users\liqihua\AppData\Local\Programs\Python\Python35\lib\site-packages\django\db\models\query.py", line 1060, in _insert
    return query.get_compiler(using=using).execute_sql(return_id)
  File "C:\Users\liqihua\AppData\Local\Programs\Python\Python35\lib\site-packages\django\db\models\sql\compiler.py", line 1106, in execute_sql
    return self.connection.ops.fetch_returned_insert_id(cursor)
  File "C:\Users\liqihua\AppData\Local\Programs\Python\Python35\lib\site-packages\django\db\backends\oracle\operations.py", line 245, in fetch_returned_insert_id
    return int(cursor._insert_id_var.getvalue())
TypeError: int() argument must be a string, a bytes-like object or a number, not 'list'
2019-01-24 15:32:35,012 [Thread-8:34636] [django.request:135] [exception:handle_uncaught_exception] [ERROR]- Internal Server Error: /admin/
Traceback (most recent call last):
  File "C:\Users\liqihua\AppData\Local\Programs\Python\Python35\lib\site-packages\django\db\backends\utils.py", line 65, in execute
    return self.cursor.execute(sql, params)
  File "C:\Users\liqihua\AppData\Local\Programs\Python\Python35\lib\site-packages\django\db\backends\oracle\base.py", line 479, in execute
    return self.cursor.execute(query, self._param_generator(params))
cx_Oracle.IntegrityError: ORA-00001: unique constraint (SCOTT.SYS_C0012212) violated

The above exception was the direct cause of the following exception:

Traceback (most recent call last):
  File "C:\Users\liqihua\AppData\Local\Programs\Python\Python35\lib\site-packages\django\core\handlers\exception.py", line 41, in inner
    response = get_response(request)
  File "C:\Users\liqihua\AppData\Local\Programs\Python\Python35\lib\site-packages\django\core\handlers\base.py", line 187, in _get_response
    response = self.process_exception_by_middleware(e, request)
  File "C:\Users\liqihua\AppData\Local\Programs\Python\Python35\lib\site-packages\django\core\handlers\base.py", line 185, in _get_response
    response = wrapped_callback(request, *callback_args, **callback_kwargs)
  File "D:\stealproject\web\django2\django2\views.py", line 89, in admin
    data = adminadd(username, usercode, usertype)
  File "D:\stealproject\web\django2\django2\views.py", line 37, in adminadd
    userinfo.objects.create(userid=k+1,username=ausername, password=busercode, type=cusertype)
  File "C:\Users\liqihua\AppData\Local\Programs\Python\Python35\lib\site-packages\django\db\models\manager.py", line 85, in manager_method
    return getattr(self.get_queryset(), name)(*args, **kwargs)
  File "C:\Users\liqihua\AppData\Local\Programs\Python\Python35\lib\site-packages\django\db\models\query.py", line 393, in create
    obj.save(force_insert=True, using=self.db)
  File "C:\Users\liqihua\AppData\Local\Programs\Python\Python35\lib\site-packages\django\db\models\base.py", line 806, in save
    force_update=force_update, update_fields=update_fields)
  File "C:\Users\liqihua\AppData\Local\Programs\Python\Python35\lib\site-packages\django\db\models\base.py", line 836, in save_base
    updated = self._save_table(raw, cls, force_insert, force_update, using, update_fields)
  File "C:\Users\liqihua\AppData\Local\Programs\Python\Python35\lib\site-packages\django\db\models\base.py", line 922, in _save_table
    result = self._do_insert(cls._base_manager, using, fields, update_pk, raw)
  File "C:\Users\liqihua\AppData\Local\Programs\Python\Python35\lib\site-packages\django\db\models\base.py", line 961, in _do_insert
    using=using, raw=raw)
  File "C:\Users\liqihua\AppData\Local\Programs\Python\Python35\lib\site-packages\django\db\models\manager.py", line 85, in manager_method
    return getattr(self.get_queryset(), name)(*args, **kwargs)
  File "C:\Users\liqihua\AppData\Local\Programs\Python\Python35\lib\site-packages\django\db\models\query.py", line 1060, in _insert
    return query.get_compiler(using=using).execute_sql(return_id)
  File "C:\Users\liqihua\AppData\Local\Programs\Python\Python35\lib\site-packages\django\db\models\sql\compiler.py", line 1099, in execute_sql
    cursor.execute(sql, params)
  File "C:\Users\liqihua\AppData\Local\Programs\Python\Python35\lib\site-packages\django\db\backends\utils.py", line 80, in execute
    return super(CursorDebugWrapper, self).execute(sql, params)
  File "C:\Users\liqihua\AppData\Local\Programs\Python\Python35\lib\site-packages\django\db\backends\utils.py", line 65, in execute
    return self.cursor.execute(sql, params)
  File "C:\Users\liqihua\AppData\Local\Programs\Python\Python35\lib\site-packages\django\db\utils.py", line 94, in __exit__
    six.reraise(dj_exc_type, dj_exc_value, traceback)
  File "C:\Users\liqihua\AppData\Local\Programs\Python\Python35\lib\site-packages\django\utils\six.py", line 685, in reraise
    raise value.with_traceback(tb)
  File "C:\Users\liqihua\AppData\Local\Programs\Python\Python35\lib\site-packages\django\db\backends\utils.py", line 65, in execute
    return self.cursor.execute(sql, params)
  File "C:\Users\liqihua\AppData\Local\Programs\Python\Python35\lib\site-packages\django\db\backends\oracle\base.py", line 479, in execute
    return self.cursor.execute(query, self._param_generator(params))
django.db.utils.IntegrityError: ORA-00001: unique constraint (SCOTT.SYS_C0012212) violated
2019-01-24 15:33:14,038 [Thread-3:37056] [django.request:135] [exception:handle_uncaught_exception] [ERROR]- Internal Server Error: /
Traceback (most recent call last):
  File "C:\Users\liqihua\AppData\Local\Programs\Python\Python35\lib\site-packages\django\core\handlers\exception.py", line 41, in inner
    response = get_response(request)
  File "C:\Users\liqihua\AppData\Local\Programs\Python\Python35\lib\site-packages\django\core\handlers\base.py", line 187, in _get_response
    response = self.process_exception_by_middleware(e, request)
  File "C:\Users\liqihua\AppData\Local\Programs\Python\Python35\lib\site-packages\django\core\handlers\base.py", line 185, in _get_response
    response = wrapped_callback(request, *callback_args, **callback_kwargs)
  File "D:\stealproject\web\django2\django2\views.py", line 67, in login
    loginmark(username)
  File "D:\stealproject\web\django2\django2\views.py", line 31, in loginmark
    loginhistory.objects.create(userid=uid,username=ausername)
  File "C:\Users\liqihua\AppData\Local\Programs\Python\Python35\lib\site-packages\django\db\models\manager.py", line 85, in manager_method
    return getattr(self.get_queryset(), name)(*args, **kwargs)
  File "C:\Users\liqihua\AppData\Local\Programs\Python\Python35\lib\site-packages\django\db\models\query.py", line 393, in create
    obj.save(force_insert=True, using=self.db)
  File "C:\Users\liqihua\AppData\Local\Programs\Python\Python35\lib\site-packages\django\db\models\base.py", line 806, in save
    force_update=force_update, update_fields=update_fields)
  File "C:\Users\liqihua\AppData\Local\Programs\Python\Python35\lib\site-packages\django\db\models\base.py", line 836, in save_base
    updated = self._save_table(raw, cls, force_insert, force_update, using, update_fields)
  File "C:\Users\liqihua\AppData\Local\Programs\Python\Python35\lib\site-packages\django\db\models\base.py", line 922, in _save_table
    result = self._do_insert(cls._base_manager, using, fields, update_pk, raw)
  File "C:\Users\liqihua\AppData\Local\Programs\Python\Python35\lib\site-packages\django\db\models\base.py", line 961, in _do_insert
    using=using, raw=raw)
  File "C:\Users\liqihua\AppData\Local\Programs\Python\Python35\lib\site-packages\django\db\models\manager.py", line 85, in manager_method
    return getattr(self.get_queryset(), name)(*args, **kwargs)
  File "C:\Users\liqihua\AppData\Local\Programs\Python\Python35\lib\site-packages\django\db\models\query.py", line 1060, in _insert
    return query.get_compiler(using=using).execute_sql(return_id)
  File "C:\Users\liqihua\AppData\Local\Programs\Python\Python35\lib\site-packages\django\db\models\sql\compiler.py", line 1106, in execute_sql
    return self.connection.ops.fetch_returned_insert_id(cursor)
  File "C:\Users\liqihua\AppData\Local\Programs\Python\Python35\lib\site-packages\django\db\backends\oracle\operations.py", line 245, in fetch_returned_insert_id
    return int(cursor._insert_id_var.getvalue())
TypeError: int() argument must be a string, a bytes-like object or a number, not 'list'
2019-01-24 15:38:04,951 [Thread-3:35832] [django.request:135] [exception:handle_uncaught_exception] [ERROR]- Internal Server Error: /
Traceback (most recent call last):
  File "C:\Users\liqihua\AppData\Local\Programs\Python\Python35\lib\site-packages\django\core\handlers\exception.py", line 41, in inner
    response = get_response(request)
  File "C:\Users\liqihua\AppData\Local\Programs\Python\Python35\lib\site-packages\django\core\handlers\base.py", line 187, in _get_response
    response = self.process_exception_by_middleware(e, request)
  File "C:\Users\liqihua\AppData\Local\Programs\Python\Python35\lib\site-packages\django\core\handlers\base.py", line 185, in _get_response
    response = wrapped_callback(request, *callback_args, **callback_kwargs)
  File "D:\stealproject\web\django2\django2\views.py", line 67, in login
    loginmark(username)
  File "D:\stealproject\web\django2\django2\views.py", line 31, in loginmark
    loginhistory.objects.create(userid=uid,username=ausername)
  File "C:\Users\liqihua\AppData\Local\Programs\Python\Python35\lib\site-packages\django\db\models\manager.py", line 85, in manager_method
    return getattr(self.get_queryset(), name)(*args, **kwargs)
  File "C:\Users\liqihua\AppData\Local\Programs\Python\Python35\lib\site-packages\django\db\models\query.py", line 393, in create
    obj.save(force_insert=True, using=self.db)
  File "C:\Users\liqihua\AppData\Local\Programs\Python\Python35\lib\site-packages\django\db\models\base.py", line 806, in save
    force_update=force_update, update_fields=update_fields)
  File "C:\Users\liqihua\AppData\Local\Programs\Python\Python35\lib\site-packages\django\db\models\base.py", line 836, in save_base
    updated = self._save_table(raw, cls, force_insert, force_update, using, update_fields)
  File "C:\Users\liqihua\AppData\Local\Programs\Python\Python35\lib\site-packages\django\db\models\base.py", line 922, in _save_table
    result = self._do_insert(cls._base_manager, using, fields, update_pk, raw)
  File "C:\Users\liqihua\AppData\Local\Programs\Python\Python35\lib\site-packages\django\db\models\base.py", line 961, in _do_insert
    using=using, raw=raw)
  File "C:\Users\liqihua\AppData\Local\Programs\Python\Python35\lib\site-packages\django\db\models\manager.py", line 85, in manager_method
    return getattr(self.get_queryset(), name)(*args, **kwargs)
  File "C:\Users\liqihua\AppData\Local\Programs\Python\Python35\lib\site-packages\django\db\models\query.py", line 1060, in _insert
    return query.get_compiler(using=using).execute_sql(return_id)
  File "C:\Users\liqihua\AppData\Local\Programs\Python\Python35\lib\site-packages\django\db\models\sql\compiler.py", line 1106, in execute_sql
    return self.connection.ops.fetch_returned_insert_id(cursor)
  File "C:\Users\liqihua\AppData\Local\Programs\Python\Python35\lib\site-packages\django\db\backends\oracle\operations.py", line 245, in fetch_returned_insert_id
    return int(cursor._insert_id_var.getvalue())
TypeError: int() argument must be a string, a bytes-like object or a number, not 'list'
2019-01-24 15:39:49,792 [Thread-6:38592] [django.request:152] [base:get_response] [WARNING]- Not Found: /favicon.ico
2019-01-24 15:39:51,838 [Thread-7:38812] [django.request:135] [exception:handle_uncaught_exception] [ERROR]- Internal Server Error: /
Traceback (most recent call last):
  File "C:\Users\liqihua\AppData\Local\Programs\Python\Python35\lib\site-packages\django\core\handlers\exception.py", line 41, in inner
    response = get_response(request)
  File "C:\Users\liqihua\AppData\Local\Programs\Python\Python35\lib\site-packages\django\core\handlers\base.py", line 187, in _get_response
    response = self.process_exception_by_middleware(e, request)
  File "C:\Users\liqihua\AppData\Local\Programs\Python\Python35\lib\site-packages\django\core\handlers\base.py", line 185, in _get_response
    response = wrapped_callback(request, *callback_args, **callback_kwargs)
  File "D:\stealproject\web\django2\django2\views.py", line 67, in login
    loginmark(username)
  File "D:\stealproject\web\django2\django2\views.py", line 31, in loginmark
    loginhistory.objects.create(userid=uid,username=ausername)
  File "C:\Users\liqihua\AppData\Local\Programs\Python\Python35\lib\site-packages\django\db\models\manager.py", line 85, in manager_method
    return getattr(self.get_queryset(), name)(*args, **kwargs)
  File "C:\Users\liqihua\AppData\Local\Programs\Python\Python35\lib\site-packages\django\db\models\query.py", line 393, in create
    obj.save(force_insert=True, using=self.db)
  File "C:\Users\liqihua\AppData\Local\Programs\Python\Python35\lib\site-packages\django\db\models\base.py", line 806, in save
    force_update=force_update, update_fields=update_fields)
  File "C:\Users\liqihua\AppData\Local\Programs\Python\Python35\lib\site-packages\django\db\models\base.py", line 836, in save_base
    updated = self._save_table(raw, cls, force_insert, force_update, using, update_fields)
  File "C:\Users\liqihua\AppData\Local\Programs\Python\Python35\lib\site-packages\django\db\models\base.py", line 922, in _save_table
    result = self._do_insert(cls._base_manager, using, fields, update_pk, raw)
  File "C:\Users\liqihua\AppData\Local\Programs\Python\Python35\lib\site-packages\django\db\models\base.py", line 961, in _do_insert
    using=using, raw=raw)
  File "C:\Users\liqihua\AppData\Local\Programs\Python\Python35\lib\site-packages\django\db\models\manager.py", line 85, in manager_method
    return getattr(self.get_queryset(), name)(*args, **kwargs)
  File "C:\Users\liqihua\AppData\Local\Programs\Python\Python35\lib\site-packages\django\db\models\query.py", line 1060, in _insert
    return query.get_compiler(using=using).execute_sql(return_id)
  File "C:\Users\liqihua\AppData\Local\Programs\Python\Python35\lib\site-packages\django\db\models\sql\compiler.py", line 1106, in execute_sql
    return self.connection.ops.fetch_returned_insert_id(cursor)
  File "C:\Users\liqihua\AppData\Local\Programs\Python\Python35\lib\site-packages\django\db\backends\oracle\operations.py", line 245, in fetch_returned_insert_id
    return int(cursor._insert_id_var.getvalue())
TypeError: int() argument must be a string, a bytes-like object or a number, not 'list'
2019-01-24 15:40:47,969 [Thread-3:11204] [django.request:135] [exception:handle_uncaught_exception] [ERROR]- Internal Server Error: /
Traceback (most recent call last):
  File "C:\Users\liqihua\AppData\Local\Programs\Python\Python35\lib\site-packages\django\db\backends\utils.py", line 65, in execute
    return self.cursor.execute(sql, params)
  File "C:\Users\liqihua\AppData\Local\Programs\Python\Python35\lib\site-packages\django\db\backends\oracle\base.py", line 479, in execute
    return self.cursor.execute(query, self._param_generator(params))
cx_Oracle.IntegrityError: ORA-01400: cannot insert NULL into ("SCOTT"."DJANGO2_LOGINHISTORY"."USERID")

The above exception was the direct cause of the following exception:

Traceback (most recent call last):
  File "C:\Users\liqihua\AppData\Local\Programs\Python\Python35\lib\site-packages\django\core\handlers\exception.py", line 41, in inner
    response = get_response(request)
  File "C:\Users\liqihua\AppData\Local\Programs\Python\Python35\lib\site-packages\django\core\handlers\base.py", line 187, in _get_response
    response = self.process_exception_by_middleware(e, request)
  File "C:\Users\liqihua\AppData\Local\Programs\Python\Python35\lib\site-packages\django\core\handlers\base.py", line 185, in _get_response
    response = wrapped_callback(request, *callback_args, **callback_kwargs)
  File "D:\stealproject\web\django2\django2\views.py", line 67, in login
    loginmark(username)
  File "D:\stealproject\web\django2\django2\views.py", line 31, in loginmark
    loginhistory.objects.create(username=ausername)
  File "C:\Users\liqihua\AppData\Local\Programs\Python\Python35\lib\site-packages\django\db\models\manager.py", line 85, in manager_method
    return getattr(self.get_queryset(), name)(*args, **kwargs)
  File "C:\Users\liqihua\AppData\Local\Programs\Python\Python35\lib\site-packages\django\db\models\query.py", line 393, in create
    obj.save(force_insert=True, using=self.db)
  File "C:\Users\liqihua\AppData\Local\Programs\Python\Python35\lib\site-packages\django\db\models\base.py", line 806, in save
    force_update=force_update, update_fields=update_fields)
  File "C:\Users\liqihua\AppData\Local\Programs\Python\Python35\lib\site-packages\django\db\models\base.py", line 836, in save_base
    updated = self._save_table(raw, cls, force_insert, force_update, using, update_fields)
  File "C:\Users\liqihua\AppData\Local\Programs\Python\Python35\lib\site-packages\django\db\models\base.py", line 922, in _save_table
    result = self._do_insert(cls._base_manager, using, fields, update_pk, raw)
  File "C:\Users\liqihua\AppData\Local\Programs\Python\Python35\lib\site-packages\django\db\models\base.py", line 961, in _do_insert
    using=using, raw=raw)
  File "C:\Users\liqihua\AppData\Local\Programs\Python\Python35\lib\site-packages\django\db\models\manager.py", line 85, in manager_method
    return getattr(self.get_queryset(), name)(*args, **kwargs)
  File "C:\Users\liqihua\AppData\Local\Programs\Python\Python35\lib\site-packages\django\db\models\query.py", line 1060, in _insert
    return query.get_compiler(using=using).execute_sql(return_id)
  File "C:\Users\liqihua\AppData\Local\Programs\Python\Python35\lib\site-packages\django\db\models\sql\compiler.py", line 1099, in execute_sql
    cursor.execute(sql, params)
  File "C:\Users\liqihua\AppData\Local\Programs\Python\Python35\lib\site-packages\django\db\backends\utils.py", line 80, in execute
    return super(CursorDebugWrapper, self).execute(sql, params)
  File "C:\Users\liqihua\AppData\Local\Programs\Python\Python35\lib\site-packages\django\db\backends\utils.py", line 65, in execute
    return self.cursor.execute(sql, params)
  File "C:\Users\liqihua\AppData\Local\Programs\Python\Python35\lib\site-packages\django\db\utils.py", line 94, in __exit__
    six.reraise(dj_exc_type, dj_exc_value, traceback)
  File "C:\Users\liqihua\AppData\Local\Programs\Python\Python35\lib\site-packages\django\utils\six.py", line 685, in reraise
    raise value.with_traceback(tb)
  File "C:\Users\liqihua\AppData\Local\Programs\Python\Python35\lib\site-packages\django\db\backends\utils.py", line 65, in execute
    return self.cursor.execute(sql, params)
  File "C:\Users\liqihua\AppData\Local\Programs\Python\Python35\lib\site-packages\django\db\backends\oracle\base.py", line 479, in execute
    return self.cursor.execute(query, self._param_generator(params))
django.db.utils.IntegrityError: ORA-01400: cannot insert NULL into ("SCOTT"."DJANGO2_LOGINHISTORY"."USERID")
2019-01-24 15:41:08,029 [Thread-3:35216] [django.request:135] [exception:handle_uncaught_exception] [ERROR]- Internal Server Error: /
Traceback (most recent call last):
  File "C:\Users\liqihua\AppData\Local\Programs\Python\Python35\lib\site-packages\django\core\handlers\exception.py", line 41, in inner
    response = get_response(request)
  File "C:\Users\liqihua\AppData\Local\Programs\Python\Python35\lib\site-packages\django\core\handlers\base.py", line 187, in _get_response
    response = self.process_exception_by_middleware(e, request)
  File "C:\Users\liqihua\AppData\Local\Programs\Python\Python35\lib\site-packages\django\core\handlers\base.py", line 185, in _get_response
    response = wrapped_callback(request, *callback_args, **callback_kwargs)
  File "D:\stealproject\web\django2\django2\views.py", line 67, in login
    loginmark(username)
  File "D:\stealproject\web\django2\django2\views.py", line 31, in loginmark
    loginhistory.objects.create(userid=uid)
  File "C:\Users\liqihua\AppData\Local\Programs\Python\Python35\lib\site-packages\django\db\models\manager.py", line 85, in manager_method
    return getattr(self.get_queryset(), name)(*args, **kwargs)
  File "C:\Users\liqihua\AppData\Local\Programs\Python\Python35\lib\site-packages\django\db\models\query.py", line 393, in create
    obj.save(force_insert=True, using=self.db)
  File "C:\Users\liqihua\AppData\Local\Programs\Python\Python35\lib\site-packages\django\db\models\base.py", line 806, in save
    force_update=force_update, update_fields=update_fields)
  File "C:\Users\liqihua\AppData\Local\Programs\Python\Python35\lib\site-packages\django\db\models\base.py", line 836, in save_base
    updated = self._save_table(raw, cls, force_insert, force_update, using, update_fields)
  File "C:\Users\liqihua\AppData\Local\Programs\Python\Python35\lib\site-packages\django\db\models\base.py", line 922, in _save_table
    result = self._do_insert(cls._base_manager, using, fields, update_pk, raw)
  File "C:\Users\liqihua\AppData\Local\Programs\Python\Python35\lib\site-packages\django\db\models\base.py", line 961, in _do_insert
    using=using, raw=raw)
  File "C:\Users\liqihua\AppData\Local\Programs\Python\Python35\lib\site-packages\django\db\models\manager.py", line 85, in manager_method
    return getattr(self.get_queryset(), name)(*args, **kwargs)
  File "C:\Users\liqihua\AppData\Local\Programs\Python\Python35\lib\site-packages\django\db\models\query.py", line 1060, in _insert
    return query.get_compiler(using=using).execute_sql(return_id)
  File "C:\Users\liqihua\AppData\Local\Programs\Python\Python35\lib\site-packages\django\db\models\sql\compiler.py", line 1106, in execute_sql
    return self.connection.ops.fetch_returned_insert_id(cursor)
  File "C:\Users\liqihua\AppData\Local\Programs\Python\Python35\lib\site-packages\django\db\backends\oracle\operations.py", line 245, in fetch_returned_insert_id
    return int(cursor._insert_id_var.getvalue())
TypeError: int() argument must be a string, a bytes-like object or a number, not 'list'
2019-01-24 15:42:27,201 [Thread-3:38384] [django.request:135] [exception:handle_uncaught_exception] [ERROR]- Internal Server Error: /
Traceback (most recent call last):
  File "C:\Users\liqihua\AppData\Local\Programs\Python\Python35\lib\site-packages\django\core\handlers\exception.py", line 41, in inner
    response = get_response(request)
  File "C:\Users\liqihua\AppData\Local\Programs\Python\Python35\lib\site-packages\django\core\handlers\base.py", line 187, in _get_response
    response = self.process_exception_by_middleware(e, request)
  File "C:\Users\liqihua\AppData\Local\Programs\Python\Python35\lib\site-packages\django\core\handlers\base.py", line 185, in _get_response
    response = wrapped_callback(request, *callback_args, **callback_kwargs)
  File "D:\stealproject\web\django2\django2\views.py", line 68, in login
    loginmark(username)
  File "D:\stealproject\web\django2\django2\views.py", line 32, in loginmark
    loginhistory.objects.create(userid=uid,username=ausername)
  File "C:\Users\liqihua\AppData\Local\Programs\Python\Python35\lib\site-packages\django\db\models\manager.py", line 85, in manager_method
    return getattr(self.get_queryset(), name)(*args, **kwargs)
  File "C:\Users\liqihua\AppData\Local\Programs\Python\Python35\lib\site-packages\django\db\models\query.py", line 393, in create
    obj.save(force_insert=True, using=self.db)
  File "C:\Users\liqihua\AppData\Local\Programs\Python\Python35\lib\site-packages\django\db\models\base.py", line 806, in save
    force_update=force_update, update_fields=update_fields)
  File "C:\Users\liqihua\AppData\Local\Programs\Python\Python35\lib\site-packages\django\db\models\base.py", line 836, in save_base
    updated = self._save_table(raw, cls, force_insert, force_update, using, update_fields)
  File "C:\Users\liqihua\AppData\Local\Programs\Python\Python35\lib\site-packages\django\db\models\base.py", line 922, in _save_table
    result = self._do_insert(cls._base_manager, using, fields, update_pk, raw)
  File "C:\Users\liqihua\AppData\Local\Programs\Python\Python35\lib\site-packages\django\db\models\base.py", line 961, in _do_insert
    using=using, raw=raw)
  File "C:\Users\liqihua\AppData\Local\Programs\Python\Python35\lib\site-packages\django\db\models\manager.py", line 85, in manager_method
    return getattr(self.get_queryset(), name)(*args, **kwargs)
  File "C:\Users\liqihua\AppData\Local\Programs\Python\Python35\lib\site-packages\django\db\models\query.py", line 1060, in _insert
    return query.get_compiler(using=using).execute_sql(return_id)
  File "C:\Users\liqihua\AppData\Local\Programs\Python\Python35\lib\site-packages\django\db\models\sql\compiler.py", line 1106, in execute_sql
    return self.connection.ops.fetch_returned_insert_id(cursor)
  File "C:\Users\liqihua\AppData\Local\Programs\Python\Python35\lib\site-packages\django\db\backends\oracle\operations.py", line 245, in fetch_returned_insert_id
    return int(cursor._insert_id_var.getvalue())
TypeError: int() argument must be a string, a bytes-like object or a number, not 'list'
2019-01-24 15:42:44,697 [Thread-3:34900] [django.request:135] [exception:handle_uncaught_exception] [ERROR]- Internal Server Error: /
Traceback (most recent call last):
  File "C:\Users\liqihua\AppData\Local\Programs\Python\Python35\lib\site-packages\django\core\handlers\exception.py", line 41, in inner
    response = get_response(request)
  File "C:\Users\liqihua\AppData\Local\Programs\Python\Python35\lib\site-packages\django\core\handlers\base.py", line 187, in _get_response
    response = self.process_exception_by_middleware(e, request)
  File "C:\Users\liqihua\AppData\Local\Programs\Python\Python35\lib\site-packages\django\core\handlers\base.py", line 185, in _get_response
    response = wrapped_callback(request, *callback_args, **callback_kwargs)
  File "D:\stealproject\web\django2\django2\views.py", line 68, in login
    loginmark(username)
  File "D:\stealproject\web\django2\django2\views.py", line 32, in loginmark
    loginhistory.objects.create(userid=2,username=ausername)
  File "C:\Users\liqihua\AppData\Local\Programs\Python\Python35\lib\site-packages\django\db\models\manager.py", line 85, in manager_method
    return getattr(self.get_queryset(), name)(*args, **kwargs)
  File "C:\Users\liqihua\AppData\Local\Programs\Python\Python35\lib\site-packages\django\db\models\query.py", line 393, in create
    obj.save(force_insert=True, using=self.db)
  File "C:\Users\liqihua\AppData\Local\Programs\Python\Python35\lib\site-packages\django\db\models\base.py", line 806, in save
    force_update=force_update, update_fields=update_fields)
  File "C:\Users\liqihua\AppData\Local\Programs\Python\Python35\lib\site-packages\django\db\models\base.py", line 836, in save_base
    updated = self._save_table(raw, cls, force_insert, force_update, using, update_fields)
  File "C:\Users\liqihua\AppData\Local\Programs\Python\Python35\lib\site-packages\django\db\models\base.py", line 922, in _save_table
    result = self._do_insert(cls._base_manager, using, fields, update_pk, raw)
  File "C:\Users\liqihua\AppData\Local\Programs\Python\Python35\lib\site-packages\django\db\models\base.py", line 961, in _do_insert
    using=using, raw=raw)
  File "C:\Users\liqihua\AppData\Local\Programs\Python\Python35\lib\site-packages\django\db\models\manager.py", line 85, in manager_method
    return getattr(self.get_queryset(), name)(*args, **kwargs)
  File "C:\Users\liqihua\AppData\Local\Programs\Python\Python35\lib\site-packages\django\db\models\query.py", line 1060, in _insert
    return query.get_compiler(using=using).execute_sql(return_id)
  File "C:\Users\liqihua\AppData\Local\Programs\Python\Python35\lib\site-packages\django\db\models\sql\compiler.py", line 1106, in execute_sql
    return self.connection.ops.fetch_returned_insert_id(cursor)
  File "C:\Users\liqihua\AppData\Local\Programs\Python\Python35\lib\site-packages\django\db\backends\oracle\operations.py", line 245, in fetch_returned_insert_id
    return int(cursor._insert_id_var.getvalue())
TypeError: int() argument must be a string, a bytes-like object or a number, not 'list'
2019-01-24 15:55:15,412 [Thread-3:22900] [django.request:152] [base:get_response] [WARNING]- Not Found: /favicon.ico
2019-01-24 15:57:15,580 [Thread-3:36164] [django.request:152] [base:get_response] [WARNING]- Not Found: /favicon.ico
2022-03-15 01:33:43,343 [uWSGIWorker1Core0:139799698159808] [django.request:230] [log:log_response] [ERROR]- Internal Server Error: /
Traceback (most recent call last):
  File "/usr/local/lib64/python3.6/site-packages/django/core/handlers/exception.py", line 47, in inner
    response = get_response(request)
  File "/usr/local/lib64/python3.6/site-packages/django/core/handlers/base.py", line 167, in _get_response
    callback, callback_args, callback_kwargs = self.resolve_request(request)
  File "/usr/local/lib64/python3.6/site-packages/django/core/handlers/base.py", line 290, in resolve_request
    resolver_match = resolver.resolve(request.path_info)
  File "/usr/local/lib64/python3.6/site-packages/django/urls/resolvers.py", line 560, in resolve
    for pattern in self.url_patterns:
  File "/usr/local/lib64/python3.6/site-packages/django/utils/functional.py", line 48, in __get__
    res = instance.__dict__[self.name] = self.func(instance)
  File "/usr/local/lib64/python3.6/site-packages/django/urls/resolvers.py", line 602, in url_patterns
    patterns = getattr(self.urlconf_module, "urlpatterns", self.urlconf_module)
  File "/usr/local/lib64/python3.6/site-packages/django/utils/functional.py", line 48, in __get__
    res = instance.__dict__[self.name] = self.func(instance)
  File "/usr/local/lib64/python3.6/site-packages/django/urls/resolvers.py", line 595, in urlconf_module
    return import_module(self.urlconf_name)
  File "/usr/lib64/python3.6/importlib/__init__.py", line 126, in import_module
    return _bootstrap._gcd_import(name[level:], package, level)
  File "<frozen importlib._bootstrap>", line 994, in _gcd_import
  File "<frozen importlib._bootstrap>", line 971, in _find_and_load
  File "<frozen importlib._bootstrap>", line 953, in _find_and_load_unlocked
ModuleNotFoundError: No module named 'django2.urls'
2022-03-15 01:33:43,713 [uWSGIWorker1Core0:139799698159808] [django.request:230] [log:log_response] [ERROR]- Internal Server Error: /favicon.ico
Traceback (most recent call last):
  File "/usr/local/lib64/python3.6/site-packages/django/core/handlers/exception.py", line 47, in inner
    response = get_response(request)
  File "/usr/local/lib64/python3.6/site-packages/django/utils/deprecation.py", line 116, in __call__
    response = self.process_request(request)
  File "/usr/local/lib64/python3.6/site-packages/django/middleware/common.py", line 53, in process_request
    if self.should_redirect_with_slash(request):
  File "/usr/local/lib64/python3.6/site-packages/django/middleware/common.py", line 70, in should_redirect_with_slash
    if not is_valid_path(request.path_info, urlconf):
  File "/usr/local/lib64/python3.6/site-packages/django/urls/base.py", line 153, in is_valid_path
    return resolve(path, urlconf)
  File "/usr/local/lib64/python3.6/site-packages/django/urls/base.py", line 24, in resolve
    return get_resolver(urlconf).resolve(path)
  File "/usr/local/lib64/python3.6/site-packages/django/urls/resolvers.py", line 560, in resolve
    for pattern in self.url_patterns:
  File "/usr/local/lib64/python3.6/site-packages/django/utils/functional.py", line 48, in __get__
    res = instance.__dict__[self.name] = self.func(instance)
  File "/usr/local/lib64/python3.6/site-packages/django/urls/resolvers.py", line 602, in url_patterns
    patterns = getattr(self.urlconf_module, "urlpatterns", self.urlconf_module)
  File "/usr/local/lib64/python3.6/site-packages/django/utils/functional.py", line 48, in __get__
    res = instance.__dict__[self.name] = self.func(instance)
  File "/usr/local/lib64/python3.6/site-packages/django/urls/resolvers.py", line 595, in urlconf_module
    return import_module(self.urlconf_name)
  File "/usr/lib64/python3.6/importlib/__init__.py", line 126, in import_module
    return _bootstrap._gcd_import(name[level:], package, level)
  File "<frozen importlib._bootstrap>", line 994, in _gcd_import
  File "<frozen importlib._bootstrap>", line 971, in _find_and_load
  File "<frozen importlib._bootstrap>", line 953, in _find_and_load_unlocked
ModuleNotFoundError: No module named 'django2.urls'
2022-03-15 01:35:26,907 [uWSGIWorker1Core0:139622103742656] [django.request:230] [log:log_response] [ERROR]- Internal Server Error: /
Traceback (most recent call last):
  File "/usr/local/lib64/python3.6/site-packages/django/core/handlers/exception.py", line 47, in inner
    response = get_response(request)
  File "/usr/local/lib64/python3.6/site-packages/django/core/handlers/base.py", line 167, in _get_response
    callback, callback_args, callback_kwargs = self.resolve_request(request)
  File "/usr/local/lib64/python3.6/site-packages/django/core/handlers/base.py", line 290, in resolve_request
    resolver_match = resolver.resolve(request.path_info)
  File "/usr/local/lib64/python3.6/site-packages/django/urls/resolvers.py", line 560, in resolve
    for pattern in self.url_patterns:
  File "/usr/local/lib64/python3.6/site-packages/django/utils/functional.py", line 48, in __get__
    res = instance.__dict__[self.name] = self.func(instance)
  File "/usr/local/lib64/python3.6/site-packages/django/urls/resolvers.py", line 602, in url_patterns
    patterns = getattr(self.urlconf_module, "urlpatterns", self.urlconf_module)
  File "/usr/local/lib64/python3.6/site-packages/django/utils/functional.py", line 48, in __get__
    res = instance.__dict__[self.name] = self.func(instance)
  File "/usr/local/lib64/python3.6/site-packages/django/urls/resolvers.py", line 595, in urlconf_module
    return import_module(self.urlconf_name)
  File "/usr/lib64/python3.6/importlib/__init__.py", line 126, in import_module
    return _bootstrap._gcd_import(name[level:], package, level)
  File "<frozen importlib._bootstrap>", line 994, in _gcd_import
  File "<frozen importlib._bootstrap>", line 971, in _find_and_load
  File "<frozen importlib._bootstrap>", line 953, in _find_and_load_unlocked
ModuleNotFoundError: No module named 'django2.urls'
2022-03-15 01:35:27,242 [uWSGIWorker1Core0:139622103742656] [django.request:230] [log:log_response] [ERROR]- Internal Server Error: /favicon.ico
Traceback (most recent call last):
  File "/usr/local/lib64/python3.6/site-packages/django/core/handlers/exception.py", line 47, in inner
    response = get_response(request)
  File "/usr/local/lib64/python3.6/site-packages/django/utils/deprecation.py", line 116, in __call__
    response = self.process_request(request)
  File "/usr/local/lib64/python3.6/site-packages/django/middleware/common.py", line 53, in process_request
    if self.should_redirect_with_slash(request):
  File "/usr/local/lib64/python3.6/site-packages/django/middleware/common.py", line 70, in should_redirect_with_slash
    if not is_valid_path(request.path_info, urlconf):
  File "/usr/local/lib64/python3.6/site-packages/django/urls/base.py", line 153, in is_valid_path
    return resolve(path, urlconf)
  File "/usr/local/lib64/python3.6/site-packages/django/urls/base.py", line 24, in resolve
    return get_resolver(urlconf).resolve(path)
  File "/usr/local/lib64/python3.6/site-packages/django/urls/resolvers.py", line 560, in resolve
    for pattern in self.url_patterns:
  File "/usr/local/lib64/python3.6/site-packages/django/utils/functional.py", line 48, in __get__
    res = instance.__dict__[self.name] = self.func(instance)
  File "/usr/local/lib64/python3.6/site-packages/django/urls/resolvers.py", line 602, in url_patterns
    patterns = getattr(self.urlconf_module, "urlpatterns", self.urlconf_module)
  File "/usr/local/lib64/python3.6/site-packages/django/utils/functional.py", line 48, in __get__
    res = instance.__dict__[self.name] = self.func(instance)
  File "/usr/local/lib64/python3.6/site-packages/django/urls/resolvers.py", line 595, in urlconf_module
    return import_module(self.urlconf_name)
  File "/usr/lib64/python3.6/importlib/__init__.py", line 126, in import_module
    return _bootstrap._gcd_import(name[level:], package, level)
  File "<frozen importlib._bootstrap>", line 994, in _gcd_import
  File "<frozen importlib._bootstrap>", line 971, in _find_and_load
  File "<frozen importlib._bootstrap>", line 953, in _find_and_load_unlocked
ModuleNotFoundError: No module named 'django2.urls'
2022-03-15 02:26:34,521 [uWSGIWorker1Core0:140524319664320] [django.request:230] [log:log_response] [ERROR]- Internal Server Error: /
Traceback (most recent call last):
  File "/usr/local/lib64/python3.6/site-packages/django/core/handlers/exception.py", line 47, in inner
    response = get_response(request)
  File "/usr/local/lib64/python3.6/site-packages/django/core/handlers/base.py", line 167, in _get_response
    callback, callback_args, callback_kwargs = self.resolve_request(request)
  File "/usr/local/lib64/python3.6/site-packages/django/core/handlers/base.py", line 290, in resolve_request
    resolver_match = resolver.resolve(request.path_info)
  File "/usr/local/lib64/python3.6/site-packages/django/urls/resolvers.py", line 560, in resolve
    for pattern in self.url_patterns:
  File "/usr/local/lib64/python3.6/site-packages/django/utils/functional.py", line 48, in __get__
    res = instance.__dict__[self.name] = self.func(instance)
  File "/usr/local/lib64/python3.6/site-packages/django/urls/resolvers.py", line 602, in url_patterns
    patterns = getattr(self.urlconf_module, "urlpatterns", self.urlconf_module)
  File "/usr/local/lib64/python3.6/site-packages/django/utils/functional.py", line 48, in __get__
    res = instance.__dict__[self.name] = self.func(instance)
  File "/usr/local/lib64/python3.6/site-packages/django/urls/resolvers.py", line 595, in urlconf_module
    return import_module(self.urlconf_name)
  File "/usr/lib64/python3.6/importlib/__init__.py", line 126, in import_module
    return _bootstrap._gcd_import(name[level:], package, level)
  File "<frozen importlib._bootstrap>", line 994, in _gcd_import
  File "<frozen importlib._bootstrap>", line 971, in _find_and_load
  File "<frozen importlib._bootstrap>", line 955, in _find_and_load_unlocked
  File "<frozen importlib._bootstrap>", line 665, in _load_unlocked
  File "<frozen importlib._bootstrap_external>", line 678, in exec_module
  File "<frozen importlib._bootstrap>", line 219, in _call_with_frames_removed
  File "/root/liekiewaa/web/jobordera/mvc/urls.py", line 19, in <module>
    import django2.views as views
ModuleNotFoundError: No module named 'django2'
2022-03-15 02:26:34,948 [uWSGIWorker1Core0:140524319664320] [django.request:230] [log:log_response] [ERROR]- Internal Server Error: /favicon.ico
Traceback (most recent call last):
  File "/usr/local/lib64/python3.6/site-packages/django/core/handlers/exception.py", line 47, in inner
    response = get_response(request)
  File "/usr/local/lib64/python3.6/site-packages/django/utils/deprecation.py", line 116, in __call__
    response = self.process_request(request)
  File "/usr/local/lib64/python3.6/site-packages/django/middleware/common.py", line 53, in process_request
    if self.should_redirect_with_slash(request):
  File "/usr/local/lib64/python3.6/site-packages/django/middleware/common.py", line 70, in should_redirect_with_slash
    if not is_valid_path(request.path_info, urlconf):
  File "/usr/local/lib64/python3.6/site-packages/django/urls/base.py", line 153, in is_valid_path
    return resolve(path, urlconf)
  File "/usr/local/lib64/python3.6/site-packages/django/urls/base.py", line 24, in resolve
    return get_resolver(urlconf).resolve(path)
  File "/usr/local/lib64/python3.6/site-packages/django/urls/resolvers.py", line 560, in resolve
    for pattern in self.url_patterns:
  File "/usr/local/lib64/python3.6/site-packages/django/utils/functional.py", line 48, in __get__
    res = instance.__dict__[self.name] = self.func(instance)
  File "/usr/local/lib64/python3.6/site-packages/django/urls/resolvers.py", line 602, in url_patterns
    patterns = getattr(self.urlconf_module, "urlpatterns", self.urlconf_module)
  File "/usr/local/lib64/python3.6/site-packages/django/utils/functional.py", line 48, in __get__
    res = instance.__dict__[self.name] = self.func(instance)
  File "/usr/local/lib64/python3.6/site-packages/django/urls/resolvers.py", line 595, in urlconf_module
    return import_module(self.urlconf_name)
  File "/usr/lib64/python3.6/importlib/__init__.py", line 126, in import_module
    return _bootstrap._gcd_import(name[level:], package, level)
  File "<frozen importlib._bootstrap>", line 994, in _gcd_import
  File "<frozen importlib._bootstrap>", line 971, in _find_and_load
  File "<frozen importlib._bootstrap>", line 955, in _find_and_load_unlocked
  File "<frozen importlib._bootstrap>", line 665, in _load_unlocked
  File "<frozen importlib._bootstrap_external>", line 678, in exec_module
  File "<frozen importlib._bootstrap>", line 219, in _call_with_frames_removed
  File "/root/liekiewaa/web/jobordera/mvc/urls.py", line 19, in <module>
    import django2.views as views
ModuleNotFoundError: No module named 'django2'
2022-03-15 02:30:11,839 [uWSGIWorker1Core0:139804849866944] [django.request:230] [log:log_response] [ERROR]- Internal Server Error: /
Traceback (most recent call last):
  File "/usr/local/lib64/python3.6/site-packages/django/core/handlers/exception.py", line 47, in inner
    response = get_response(request)
  File "/usr/local/lib64/python3.6/site-packages/django/core/handlers/base.py", line 167, in _get_response
    callback, callback_args, callback_kwargs = self.resolve_request(request)
  File "/usr/local/lib64/python3.6/site-packages/django/core/handlers/base.py", line 290, in resolve_request
    resolver_match = resolver.resolve(request.path_info)
  File "/usr/local/lib64/python3.6/site-packages/django/urls/resolvers.py", line 560, in resolve
    for pattern in self.url_patterns:
  File "/usr/local/lib64/python3.6/site-packages/django/utils/functional.py", line 48, in __get__
    res = instance.__dict__[self.name] = self.func(instance)
  File "/usr/local/lib64/python3.6/site-packages/django/urls/resolvers.py", line 602, in url_patterns
    patterns = getattr(self.urlconf_module, "urlpatterns", self.urlconf_module)
  File "/usr/local/lib64/python3.6/site-packages/django/utils/functional.py", line 48, in __get__
    res = instance.__dict__[self.name] = self.func(instance)
  File "/usr/local/lib64/python3.6/site-packages/django/urls/resolvers.py", line 595, in urlconf_module
    return import_module(self.urlconf_name)
  File "/usr/lib64/python3.6/importlib/__init__.py", line 126, in import_module
    return _bootstrap._gcd_import(name[level:], package, level)
  File "<frozen importlib._bootstrap>", line 994, in _gcd_import
  File "<frozen importlib._bootstrap>", line 971, in _find_and_load
  File "<frozen importlib._bootstrap>", line 955, in _find_and_load_unlocked
  File "<frozen importlib._bootstrap>", line 665, in _load_unlocked
  File "<frozen importlib._bootstrap_external>", line 678, in exec_module
  File "<frozen importlib._bootstrap>", line 219, in _call_with_frames_removed
  File "/root/liekiewaa/web/jobordera/mvc/urls.py", line 19, in <module>
    import mvc.views as views
  File "/root/liekiewaa/web/jobordera/mvc/views.py", line 4, in <module>
    from django2.model import userinfo,loginhistory
ModuleNotFoundError: No module named 'django2'
2022-03-15 02:30:12,227 [uWSGIWorker1Core0:139804849866944] [django.request:230] [log:log_response] [ERROR]- Internal Server Error: /favicon.ico
Traceback (most recent call last):
  File "/usr/local/lib64/python3.6/site-packages/django/core/handlers/exception.py", line 47, in inner
    response = get_response(request)
  File "/usr/local/lib64/python3.6/site-packages/django/utils/deprecation.py", line 116, in __call__
    response = self.process_request(request)
  File "/usr/local/lib64/python3.6/site-packages/django/middleware/common.py", line 53, in process_request
    if self.should_redirect_with_slash(request):
  File "/usr/local/lib64/python3.6/site-packages/django/middleware/common.py", line 70, in should_redirect_with_slash
    if not is_valid_path(request.path_info, urlconf):
  File "/usr/local/lib64/python3.6/site-packages/django/urls/base.py", line 153, in is_valid_path
    return resolve(path, urlconf)
  File "/usr/local/lib64/python3.6/site-packages/django/urls/base.py", line 24, in resolve
    return get_resolver(urlconf).resolve(path)
  File "/usr/local/lib64/python3.6/site-packages/django/urls/resolvers.py", line 560, in resolve
    for pattern in self.url_patterns:
  File "/usr/local/lib64/python3.6/site-packages/django/utils/functional.py", line 48, in __get__
    res = instance.__dict__[self.name] = self.func(instance)
  File "/usr/local/lib64/python3.6/site-packages/django/urls/resolvers.py", line 602, in url_patterns
    patterns = getattr(self.urlconf_module, "urlpatterns", self.urlconf_module)
  File "/usr/local/lib64/python3.6/site-packages/django/utils/functional.py", line 48, in __get__
    res = instance.__dict__[self.name] = self.func(instance)
  File "/usr/local/lib64/python3.6/site-packages/django/urls/resolvers.py", line 595, in urlconf_module
    return import_module(self.urlconf_name)
  File "/usr/lib64/python3.6/importlib/__init__.py", line 126, in import_module
    return _bootstrap._gcd_import(name[level:], package, level)
  File "<frozen importlib._bootstrap>", line 994, in _gcd_import
  File "<frozen importlib._bootstrap>", line 971, in _find_and_load
  File "<frozen importlib._bootstrap>", line 955, in _find_and_load_unlocked
  File "<frozen importlib._bootstrap>", line 665, in _load_unlocked
  File "<frozen importlib._bootstrap_external>", line 678, in exec_module
  File "<frozen importlib._bootstrap>", line 219, in _call_with_frames_removed
  File "/root/liekiewaa/web/jobordera/mvc/urls.py", line 19, in <module>
    import mvc.views as views
  File "/root/liekiewaa/web/jobordera/mvc/views.py", line 4, in <module>
    from django2.model import userinfo,loginhistory
ModuleNotFoundError: No module named 'django2'
2022-03-15 02:30:46,405 [uWSGIWorker1Core0:140482883561664] [django.request:230] [log:log_response] [ERROR]- Internal Server Error: /
Traceback (most recent call last):
  File "/usr/local/lib64/python3.6/site-packages/django/core/handlers/exception.py", line 47, in inner
    response = get_response(request)
  File "/usr/local/lib64/python3.6/site-packages/django/core/handlers/base.py", line 167, in _get_response
    callback, callback_args, callback_kwargs = self.resolve_request(request)
  File "/usr/local/lib64/python3.6/site-packages/django/core/handlers/base.py", line 290, in resolve_request
    resolver_match = resolver.resolve(request.path_info)
  File "/usr/local/lib64/python3.6/site-packages/django/urls/resolvers.py", line 560, in resolve
    for pattern in self.url_patterns:
  File "/usr/local/lib64/python3.6/site-packages/django/utils/functional.py", line 48, in __get__
    res = instance.__dict__[self.name] = self.func(instance)
  File "/usr/local/lib64/python3.6/site-packages/django/urls/resolvers.py", line 602, in url_patterns
    patterns = getattr(self.urlconf_module, "urlpatterns", self.urlconf_module)
  File "/usr/local/lib64/python3.6/site-packages/django/utils/functional.py", line 48, in __get__
    res = instance.__dict__[self.name] = self.func(instance)
  File "/usr/local/lib64/python3.6/site-packages/django/urls/resolvers.py", line 595, in urlconf_module
    return import_module(self.urlconf_name)
  File "/usr/lib64/python3.6/importlib/__init__.py", line 126, in import_module
    return _bootstrap._gcd_import(name[level:], package, level)
  File "<frozen importlib._bootstrap>", line 994, in _gcd_import
  File "<frozen importlib._bootstrap>", line 971, in _find_and_load
  File "<frozen importlib._bootstrap>", line 955, in _find_and_load_unlocked
  File "<frozen importlib._bootstrap>", line 665, in _load_unlocked
  File "<frozen importlib._bootstrap_external>", line 678, in exec_module
  File "<frozen importlib._bootstrap>", line 219, in _call_with_frames_removed
  File "/root/liekiewaa/web/jobordera/mvc/urls.py", line 19, in <module>
    import mvc.views as views
  File "/root/liekiewaa/web/jobordera/mvc/views.py", line 10, in <module>
    from pykafka import KafkaClient,SimpleConsumer
ModuleNotFoundError: No module named 'pykafka'
2022-03-15 02:30:46,760 [uWSGIWorker1Core0:140482883561664] [django.request:230] [log:log_response] [ERROR]- Internal Server Error: /favicon.ico
Traceback (most recent call last):
  File "/usr/local/lib64/python3.6/site-packages/django/core/handlers/exception.py", line 47, in inner
    response = get_response(request)
  File "/usr/local/lib64/python3.6/site-packages/django/utils/deprecation.py", line 116, in __call__
    response = self.process_request(request)
  File "/usr/local/lib64/python3.6/site-packages/django/middleware/common.py", line 53, in process_request
    if self.should_redirect_with_slash(request):
  File "/usr/local/lib64/python3.6/site-packages/django/middleware/common.py", line 70, in should_redirect_with_slash
    if not is_valid_path(request.path_info, urlconf):
  File "/usr/local/lib64/python3.6/site-packages/django/urls/base.py", line 153, in is_valid_path
    return resolve(path, urlconf)
  File "/usr/local/lib64/python3.6/site-packages/django/urls/base.py", line 24, in resolve
    return get_resolver(urlconf).resolve(path)
  File "/usr/local/lib64/python3.6/site-packages/django/urls/resolvers.py", line 560, in resolve
    for pattern in self.url_patterns:
  File "/usr/local/lib64/python3.6/site-packages/django/utils/functional.py", line 48, in __get__
    res = instance.__dict__[self.name] = self.func(instance)
  File "/usr/local/lib64/python3.6/site-packages/django/urls/resolvers.py", line 602, in url_patterns
    patterns = getattr(self.urlconf_module, "urlpatterns", self.urlconf_module)
  File "/usr/local/lib64/python3.6/site-packages/django/utils/functional.py", line 48, in __get__
    res = instance.__dict__[self.name] = self.func(instance)
  File "/usr/local/lib64/python3.6/site-packages/django/urls/resolvers.py", line 595, in urlconf_module
    return import_module(self.urlconf_name)
  File "/usr/lib64/python3.6/importlib/__init__.py", line 126, in import_module
    return _bootstrap._gcd_import(name[level:], package, level)
  File "<frozen importlib._bootstrap>", line 994, in _gcd_import
  File "<frozen importlib._bootstrap>", line 971, in _find_and_load
  File "<frozen importlib._bootstrap>", line 955, in _find_and_load_unlocked
  File "<frozen importlib._bootstrap>", line 665, in _load_unlocked
  File "<frozen importlib._bootstrap_external>", line 678, in exec_module
  File "<frozen importlib._bootstrap>", line 219, in _call_with_frames_removed
  File "/root/liekiewaa/web/jobordera/mvc/urls.py", line 19, in <module>
    import mvc.views as views
  File "/root/liekiewaa/web/jobordera/mvc/views.py", line 10, in <module>
    from pykafka import KafkaClient,SimpleConsumer
ModuleNotFoundError: No module named 'pykafka'
2022-03-15 02:31:08,777 [uWSGIWorker1Core0:139621667514560] [django.request:230] [log:log_response] [WARNING]- Not Found: /favicon.ico
2022-03-15 02:31:45,479 [uWSGIWorker1Core0:139621667514560] [django.request:230] [log:log_response] [ERROR]- Internal Server Error: /
Traceback (most recent call last):
  File "/usr/local/lib64/python3.6/site-packages/django/db/backends/utils.py", line 84, in _execute
    return self.cursor.execute(sql, params)
  File "/usr/local/lib64/python3.6/site-packages/django/db/backends/sqlite3/base.py", line 423, in execute
    return Database.Cursor.execute(self, query, params)
sqlite3.OperationalError: no such table: mvc_userinfo

The above exception was the direct cause of the following exception:

Traceback (most recent call last):
  File "/usr/local/lib64/python3.6/site-packages/django/core/handlers/exception.py", line 47, in inner
    response = get_response(request)
  File "/usr/local/lib64/python3.6/site-packages/django/core/handlers/base.py", line 181, in _get_response
    response = wrapped_callback(request, *callback_args, **callback_kwargs)
  File "/root/liekiewaa/web/jobordera/mvc/views.py", line 65, in login
    logic=logincheck(username, usercode)
  File "/root/liekiewaa/web/jobordera/mvc/views.py", line 24, in logincheck
    if result:
  File "/usr/local/lib64/python3.6/site-packages/django/db/models/query.py", line 284, in __bool__
    self._fetch_all()
  File "/usr/local/lib64/python3.6/site-packages/django/db/models/query.py", line 1324, in _fetch_all
    self._result_cache = list(self._iterable_class(self))
  File "/usr/local/lib64/python3.6/site-packages/django/db/models/query.py", line 109, in __iter__
    for row in compiler.results_iter(chunked_fetch=self.chunked_fetch, chunk_size=self.chunk_size):
  File "/usr/local/lib64/python3.6/site-packages/django/db/models/sql/compiler.py", line 1130, in results_iter
    results = self.execute_sql(MULTI, chunked_fetch=chunked_fetch, chunk_size=chunk_size)
  File "/usr/local/lib64/python3.6/site-packages/django/db/models/sql/compiler.py", line 1175, in execute_sql
    cursor.execute(sql, params)
  File "/usr/local/lib64/python3.6/site-packages/django/db/backends/utils.py", line 98, in execute
    return super().execute(sql, params)
  File "/usr/local/lib64/python3.6/site-packages/django/db/backends/utils.py", line 66, in execute
    return self._execute_with_wrappers(sql, params, many=False, executor=self._execute)
  File "/usr/local/lib64/python3.6/site-packages/django/db/backends/utils.py", line 75, in _execute_with_wrappers
    return executor(sql, params, many, context)
  File "/usr/local/lib64/python3.6/site-packages/django/db/backends/utils.py", line 84, in _execute
    return self.cursor.execute(sql, params)
  File "/usr/local/lib64/python3.6/site-packages/django/db/utils.py", line 90, in __exit__
    raise dj_exc_value.with_traceback(traceback) from exc_value
  File "/usr/local/lib64/python3.6/site-packages/django/db/backends/utils.py", line 84, in _execute
    return self.cursor.execute(sql, params)
  File "/usr/local/lib64/python3.6/site-packages/django/db/backends/sqlite3/base.py", line 423, in execute
    return Database.Cursor.execute(self, query, params)
django.db.utils.OperationalError: no such table: mvc_userinfo
2022-03-15 02:33:19,216 [uWSGIWorker1Core0:139621667514560] [django.request:230] [log:log_response] [WARNING]- Not Found: /favicon.ico
